Workbook

Sheet Raw_Data
A1: DATE | B1: MONTH - FÓRMULA NÃO ALTERAR | C1: WEEK_OF_MONTH - FÓRMULA NÃO ALTERAR | D1: BRANCH | E1: DIVISION | F1: SERVICE_TYPE | G1: SHIPMENTS | H1: KG | I1: TEUs | J1: CBM | K1: YEAR - FÓRMULA NÃO ALTERAR | L1: TYPE OF OP | M1: TYPE
A2: 46118.583 | B2: =MONTH(A2) -> 4 | C2: =WEEKNUM(A2) -> 15 | D2: CPQ | E2: SEA | F2: CONSOLIDADA | G2: 1 | J2: 0.15 | K2: =YEAR(A2) -> 2026 | L2: EXPO | M2: LCL
A3: 46118.583 | B3: =MONTH(A3) -> 4 | C3: =WEEKNUM(A3) -> 15 | D3: CPQ | E3: SEA | F3: CONSOLIDADA | G3: 1 | J3: 1.01 | K3: =YEAR(A3) -> 2026 | L3: EXPO | M3: LCL
A4: 46121.792 | B4: =MONTH(A4) -> 4 | C4: =WEEKNUM(A4) -> 15 | D4: CPQ | E4: SEA | F4: COLOADER | G4: 1 | J4: 0.766 | K4: =YEAR(A4) -> 2026 | L4: EXPO | M4: LCL
A5: 46123 | B5: =MONTH(A5) -> 4 | C5: =WEEKNUM(A5) -> 15 | D5: CPQ | E5: SEA | F5: COLOADER | G5: 1 | J5: 0.576 | K5: =YEAR(A5) -> 2026 | L5: EXPO | M5: LCL
A6: 46123 | B6: =MONTH(A6) -> 4 | C6: =WEEKNUM(A6) -> 15 | D6: CPQ | E6: SEA | F6: COLOADER | G6: 1 | J6: 3.186 | K6: =YEAR(A6) -> 2026 | L6: EXPO | M6: LCL
A7: 46118.583 | B7: =MONTH(A7) -> 4 | C7: =WEEKNUM(A7) -> 15 | D7: CPQ | E7: SEA | F7: CONSOLIDADA | G7: 1 | J7: 2.011 | K7: =YEAR(A7) -> 2026 | L7: EXPO | M7: LCL
A8: 46118.583 | B8: =MONTH(A8) -> 4 | C8: =WEEKNUM(A8) -> 15 | D8: CPQ | E8: SEA | F8: CONSOLIDADA | G8: 1 | J8: 1.769 | K8: =YEAR(A8) -> 2026 | L8: EXPO | M8: LCL
A9: 46118.583 | B9: =MONTH(A9) -> 4 | C9: =WEEKNUM(A9) -> 15 | D9: CPQ | E9: SEA | F9: CONSOLIDADA | G9: 1 | J9: 2.06 | K9: =YEAR(A9) -> 2026 | L9: EXPO | M9: LCL
A10: 46118.583 | B10: =MONTH(A10) -> 4 | C10: =WEEKNUM(A10) -> 15 | D10: CPQ | E10: SEA | F10: CONSOLIDADA | G10: 1 | J10: 5.375 | K10: =YEAR(A10) -> 2026 | L10: EXPO | M10: LCL
A11: 46119 | B11: =MONTH(A11) -> 4 | C11: =WEEKNUM(A11) -> 15 | D11: CPQ | E11: SEA | F11: COLOADER | G11: 1 | J11: 6.594 | K11: =YEAR(A11) -> 2026 | L11: EXPO | M11: LCL
A12: 46119 | B12: =MONTH(A12) -> 4 | C12: =WEEKNUM(A12) -> 15 | D12: CPQ | E12: SEA | F12: COLOADER | G12: 1 | J12: 0.99 | K12: =YEAR(A12) -> 2026 | L12: EXPO | M12: LCL
A13: 46118.583 | B13: =MONTH(A13) -> 4 | C13: =WEEKNUM(A13) -> 15 | D13: CPQ | E13: SEA | F13: CONSOLIDADA | G13: 1 | J13: 3.331 | K13: =YEAR(A13) -> 2026 | L13: EXPO | M13: LCL
... A419185: 46140 | B419185: =MONTH(A419185) -> 4 | C419185: =WEEKNUM(A419185) -> 18 | D419185: SAO | E419185: SEA | F419185: COLOADER | G419185: 1 | J419185: 3.188 | K419185: =YEAR(A419185) -> 2026 | L419185: IMPO | M419185: LCL
A419186: 46150.25 | B419186: 5 | C419186: 19 | D419186: CPQ | E419186: SEA | F419186: CONSOLIDADA | G419186: 1 | J419186: 6.12 | K419186: 2026 | L419186: EXPO | M419186: LCL
A419187: 46150.882 | B419187: 5 | C419187: 19 | D419187: CPQ | E419187: SEA | F419187: COLOADER | G419187: 1 | J419187: 1.05 | K419187: 2026 | L419187: EXPO | M419187: LCL
A419188: 46150.729 | B419188: 5 | C419188: 19 | D419188: CPQ | E419188: SEA | F419188: COLOADER | G419188: 1 | J419188: 0.55 | K419188: 2026 | L419188: EXPO | M419188: LCL
A419189: 46146.059 | B419189: 5 | C419189: 19 | D419189: CPQ | E419189: SEA | F419189: CONSOLIDADA | G419189: 1 | J419189: 1.14 | K419189: 2026 | L419189: EXPO | M419189: LCL
A419190: 46149 | B419190: 5 | C419190: 19 | D419190: CPQ | E419190: SEA | F419190: COLOADER | G419190: 1 | J419190: 1.344 | K419190: 2026 | L419190: EXPO | M419190: LCL
A419191: 46148.024 | B419191: 5 | C419191: 19 | D419191: CPQ | E419191: SEA | F419191: CONSOLIDADA | G419191: 1 | J419191: 0.638 | K419191: 2026 | L419191: EXPO | M419191: LCL
A419192: 46148.024 | B419192: 5 | C419192: 19 | D419192: CPQ | E419192: SEA | F419192: CONSOLIDADA | G419192: 1 | J419192: 0.501 | K419192: 2026 | L419192: EXPO | M419192: LCL
A419193: 46148.024 | B419193: 5 | C419193: 19 | D419193: CPQ | E419193: SEA | F419193: CONSOLIDADA | G419193: 1 | J419193: 0.24 | K419193: 2026 | L419193: EXPO | M419193: LCL
A419194: 46148.024 | B419194: 5 | C419194: 19 | D419194: CPQ | E419194: SEA | F419194: CONSOLIDADA | G419194: 1 | J419194: 2.884 | K419194: 2026 | L419194: EXPO | M419194: LCL
A419195: 46148.024 | B419195: 5 | C419195: 19 | D419195: CPQ | E419195: SEA | F419195: CONSOLIDADA | G419195: 1 | J419195: 1.344 | K419195: 2026 | L419195: EXPO | M419195: LCL
A419196: 46148.024 | B419196: 5 | C419196: 19 | D419196: CPQ | E419196: SEA | F419196: CONSOLIDADA | G419196: 1 | J419196: 3.192 | K419196: 2026 | L419196: EXPO | M419196: LCL
A419197: 46149 | B419197: 5 | C419197: 19 | D419197: CPQ | E419197: SEA | F419197: COLOADER | G419197: 1 | J419197: 4.032 | K419197: 2026 | L419197: EXPO | M419197: LCL
... A419280: 46147 | B419280: 5 | C419280: 19 | D419280: SAO | E419280: SEA | F419280: COLOADER | G419280: 1 | J419280: 1.389 | K419280: 2026 | L419280: IMPO | M419280: LCL
A419281: 46148.125 | B419281: =MONTH(A419281) -> 5 | C419281: =WEEKNUM(A419281) -> 19 | D419281: CPQ | E419281: SEA | F419281: CONSOLIDADA | G419281: 1 | J419281: 3.247 | K419281: 2026 | L419281: IMPO | M419281: LCL
A419282: 46148.125 | B419282: =MONTH(A419282) -> 5 | C419282: =WEEKNUM(A419282) -> 19 | D419282: CPQ | E419282: SEA | F419282: CONSOLIDADA | G419282: 1 | J419282: 2.884 | K419282: 2026 | L419282: IMPO | M419282: LCL
A419283: 46148.125 | B419283: =MONTH(A419283) -> 5 | C419283: =WEEKNUM(A419283) -> 19 | D419283: CPQ | E419283: SEA | F419283: CONSOLIDADA | G419283: 1 | J419283: 4.205 | K419283: 2026 | L419283: IMPO | M419283: LCL
A419284: 46148.125 | B419284: =MONTH(A419284) -> 5 | C419284: =WEEKNUM(A419284) -> 19 | D419284: CPQ | E419284: SEA | F419284: CONSOLIDADA | G419284: 1 | J419284: 1.852 | K419284: 2026 | L419284: IMPO | M419284: LCL
A419285: 46148.125 | B419285: =MONTH(A419285) -> 5 | C419285: =WEEKNUM(A419285) -> 19 | D419285: CPQ | E419285: SEA | F419285: CONSOLIDADA | G419285: 1 | J419285: 0.336 | K419285: 2026 | L419285: IMPO | M419285: LCL
A419286: 46148.125 | B419286: =MONTH(A419286) -> 5 | C419286: =WEEKNUM(A419286) -> 19 | D419286: CPQ | E419286: SEA | F419286: CONSOLIDADA | G419286: 1 | J419286: 0.34 | K419286: 2026 | L419286: IMPO | M419286: LCL
A419287: 46148 | B419287: =MONTH(A419287) -> 5 | C419287: =WEEKNUM(A419287) -> 19 | D419287: CPQ | E419287: SEA | F419287: CONSOLIDADA | G419287: 1 | J419287: 0.301 | K419287: 2026 | L419287: IMPO | M419287: LCL
A419288: 46148.125 | B419288: =MONTH(A419288) -> 5 | C419288: =WEEKNUM(A419288) -> 19 | D419288: CPQ | E419288: SEA | F419288: CONSOLIDADA | G419288: 1 | J419288: 0.696 | K419288: 2026 | L419288: IMPO | M419288: LCL
A419289: 46151.792 | B419289: =MONTH(A419289) -> 5 | C419289: =WEEKNUM(A419289) -> 19 | D419289: CPQ | E419289: SEA | F419289: CONSOLIDADA | G419289: 1 | J419289: 4.098 | K419289: 2026 | L419289: IMPO | M419289: LCL
A419290: 46148.125 | B419290: =MONTH(A419290) -> 5 | C419290: =WEEKNUM(A419290) -> 19 | D419290: CPQ | E419290: SEA | F419290: CONSOLIDADA | G419290: 1 | J419290: 4.172 | K419290: 2026 | L419290: IMPO | M419290: LCL
A419291: 46148 | B419291: =MONTH(A419291) -> 5 | C419291: =WEEKNUM(A419291) -> 19 | D419291: CPQ | E419291: SEA | F419291: CONSOLIDADA | G419291: 1 | J419291: 5.281 | K419291: 2026 | L419291: IMPO | M419291: LCL
A419292: 46148 | B419292: =MONTH(A419292) -> 5 | C419292: =WEEKNUM(A419292) -> 19 | D419292: CPQ | E419292: SEA | F419292: CONSOLIDADA | G419292: 1 | J419292: 0.152 | K419292: 2026 | L419292: IMPO | M419292: LCL
A419293: 46148 | B419293: =MONTH(A419293) -> 5 | C419293: =WEEKNUM(A419293) -> 19 | D419293: CPQ | E419293: SEA | F419293: CONSOLIDADA | G419293: 1 | J419293: 5.789 | K419293: 2026 | L419293: IMPO | M419293: LCL
...

Sheet hiddenOps
A1: BranchList | C1: WeekList | E1: DivisionList | G1: AirTypes | I1: FclTypes | K1: LclTypes | L1: CurrentYear | M1: CompareYear
A2: CPQ | C2: WEEK 5 | E2: AIR | G2: LSE | I2: EMBARQUE DIRETO | K2: COLOADER | L2: 2026 | M2: 2025
A3: CWB | C3: WEEK 6 | E3: FCL | G3: OTH | I3: EMBARQUE DSV | K3: CONSOLIDADA
A4: ITJ | C4: WEEK 7 | E4: LCL
A5: MAO | C5: WEEK 8
A6: POA | C6: WEEK 9
A7: RIO | C7: WEEK 10
A8: SAO | C8: WEEK 11
A9: SSA
A10: REC
A11: TOTAL

Sheet SEGUIR PARA PREENCHIMENTO
A1: LEGENDAS - RAW DATA
A2: MODAL | B2: AEREO | C2: FCL | D2: LCL
A3: COLUNA A | B3: DATA | C3: DATA | D3: DATA
A4: COLUNA B | B4: FÓRMULA NÃO MEXER | C4: FÓRMULA NÃO MEXER | D4: FÓRMULA NÃO MEXER
A5: COLUNA C | B5: FÓRMULA NÃO MEXER | C5: FÓRMULA NÃO MEXER | D5: FÓRMULA NÃO MEXER
A6: COLUNA D | B6: BRANCH | C6: BRANCH | D6: BRANCH
A7: COLUNA E | B7: DIVISÃO | C7: DIVISÃO | D7: DIVISÃO
A8: COLUNA F | B8: LSE/OTH | C8: EMBARQUE DIRETO OU EMBARQUE DSV | D8: COLOADER OU CONSOLIDADA
A9: COLUNA G | B9: NÚMERO DE EMBARQUES | C9: NÚMERO DE EMBARQUES | D9: NÚMERO DE EMBARQUES
A10: COLUNA H | B10: KG | C10: - | D10: -
A11: COLUNA I | B11: - | C11: TEUs | D11: -
A12: COLUNA J | B12: - | C12: - | D12: CBM
A13: COLUNA K | B13: FÓRMULA NÃO MEXER | C13: FÓRMULA NÃO MEXER | D13: FÓRMULA NÃO MEXER
... A15: COLUNA M | B15: - | C15: FCL | D15: LCL

Sheet CHART - INFO
A1: EMBARQUES IMPO (2025 vs 2026) | F1: EMBARQUES EXPO (2025 vs 2026) | K1: Week | L1: CPQ | M1: CWB | N1: ITJ | O1: MAO | P1: POA | Q1: RIO | R1: SAO | S1: SSA | U1: Week | V1: CPQ | W1: CWB | X1: ITJ | Y1: MAO | Z1: POA | AA1: RIO | AB1: SAO | AC1: SSA
A2: Week | B2: 2025 | C2: 2026 | F2: Week | G2: 2025 | H2: 2026 | K2: 15 | L2: =SUMIFS(Raw_Data!$G:$G,Raw_Data!$C:$C,$K2,Raw_Data!$K:$K,2026,Raw_Data!$M:$M,"LCL",Raw_Data!$L:$L,"IMPO",Raw_Data!$D:$D,L$1) -> 71 | M2: =SUMIFS(Raw_Data!$G:$G,Raw_Data!$C:$C,$K2,Raw_Data!$K:$K,2026,Raw_Data!$M:$M,"LCL",Raw_Data!$L:$L,"IMPO",Raw_Data!$D:$D,M$1) -> 14 | N2: =SUMIFS(Raw_Data!$G:$G,Raw_Data!$C:$C,$K2,Raw_Data!$K:$K,2026,Raw_Data!$M:$M,"LCL",Raw_Data!$L:$L,"IMPO",Raw_Data!$D:$D,N$1) -> 1 | O2: =SUMIFS(Raw_Data!$G:$G,Raw_Data!$C:$C,$K2,Raw_Data!$K:$K,2026,Raw_Data!$M:$M,"LCL",Raw_Data!$L:$L,"IMPO",Raw_Data!$D:$D,O$1) -> 0 | P2: =SUMIFS(Raw_Data!$G:$G,Raw_Data!$C:$C,$K2,Raw_Data!$K:$K,2026,Raw_Data!$M:$M,"LCL",Raw_Data!$L:$L,"IMPO",Raw_Data!$D:$D,P$1) -> 13 | Q2: =SUMIFS(Raw_Data!$G:$G,Raw_Data!$C:$C,$K2,Raw_Data!$K:$K,2026,Raw_Data!$M:$M,"LCL",Raw_Data!$L:$L,"IMPO",Raw_Data!$D:$D,Q$1) -> 17 | R2: =SUMIFS(Raw_Data!$G:$G,Raw_Data!$C:$C,$K2,Raw_Data!$K:$K,2026,Raw_Data!$M:$M,"LCL",Raw_Data!$L:$L,"IMPO",Raw_Data!$D:$D,R$1) -> 120 | S2: =SUMIFS(Raw_Data!$G:$G,Raw_Data!$C:$C,$K2,Raw_Data!$K:$K,2026,Raw_Data!$M:$M,"LCL",Raw_Data!$L:$L,"IMPO",Raw_Data!$D:$D,S$1) -> 0 | U2: 15 | V2: =SUMIFS(Raw_Data!$J:$J,Raw_Data!$C:$C,$K2,Raw_Data!$K:$K,2026,Raw_Data!$M:$M,"LCL",Raw_Data!$L:$L,"IMPO",Raw_Data!$D:$D,V$1) -> 222.783 | W2: =SUMIFS(Raw_Data!$J:$J,Raw_Data!$C:$C,$K2,Raw_Data!$K:$K,2026,Raw_Data!$M:$M,"LCL",Raw_Data!$L:$L,"IMPO",Raw_Data!$D:$D,W$1) -> 64.158 | X2: =SUMIFS(Raw_Data!$J:$J,Raw_Data!$C:$C,$K2,Raw_Data!$K:$K,2026,Raw_Data!$M:$M,"LCL",Raw_Data!$L:$L,"IMPO",Raw_Data!$D:$D,X$1) -> 0.743 | Y2: =SUMIFS(Raw_Data!$J:$J,Raw_Data!$C:$C,$K2,Raw_Data!$K:$K,2026,Raw_Data!$M:$M,"LCL",Raw_Data!$L:$L,"IMPO",Raw_Data!$D:$D,Y$1) -> 0 | Z2: =SUMIFS(Raw_Data!$J:$J,Raw_Data!$C:$C,$K2,Raw_Data!$K:$K,2026,Raw_Data!$M:$M,"LCL",Raw_Data!$L:$L,"IMPO",Raw_Data!$D:$D,Z$1) -> 43.11 | AA2: =SUMIFS(Raw_Data!$J:$J,Raw_Data!$C:$C,$K2,Raw_Data!$K:$K,2026,Raw_Data!$M:$M,"LCL",Raw_Data!$L:$L,"IMPO",Raw_Data!$D:$D,AA$1) -> 67.233 | AB2: =SUMIFS(Raw_Data!$J:$J,Raw_Data!$C:$C,$K2,Raw_Data!$K:$K,2026,Raw_Data!$M:$M,"LCL",Raw_Data!$L:$L,"IMPO",Raw_Data!$D:$D,AB$1) -> 410.823 | AC2: =SUMIFS(Raw_Data!$J:$J,Raw_Data!$C:$C,$K2,Raw_Data!$K:$K,2026,Raw_Data!$M:$M,"LCL",Raw_Data!$L:$L,"IMPO",Raw_Data!$D:$D,AC$1) -> 0
A3: 15 | B3: =SUMIFS(Raw_Data!$G:$G,Raw_Data!$C:$C,$A3,Raw_Data!$K:$K,B$2,Raw_Data!$M:$M,"LCL",Raw_Data!$L:$L,"IMPO") -> 0 | C3: =SUMIFS(Raw_Data!$G:$G,Raw_Data!$C:$C,$A3,Raw_Data!$K:$K,C$2,Raw_Data!$M:$M,"LCL",Raw_Data!$L:$L,"IMPO") -> 236 | F3: 15 | G3: =SUMIFS(Raw_Data!$G:$G,Raw_Data!$C:$C,$F3,Raw_Data!$K:$K,G$2,Raw_Data!$M:$M,"LCL",Raw_Data!$L:$L,"EXPO") -> 0 | H3: =SUMIFS(Raw_Data!$G:$G,Raw_Data!$C:$C,$F3,Raw_Data!$K:$K,H$2,Raw_Data!$M:$M,"LCL",Raw_Data!$L:$L,"EXPO") -> 77 | K3: 16 | L3: =SUMIFS(Raw_Data!$G:$G,Raw_Data!$C:$C,$K3,Raw_Data!$K:$K,2026,Raw_Data!$M:$M,"LCL",Raw_Data!$L:$L,"IMPO",Raw_Data!$D:$D,L$1) -> 67 | M3: =SUMIFS(Raw_Data!$G:$G,Raw_Data!$C:$C,$K3,Raw_Data!$K:$K,2026,Raw_Data!$M:$M,"LCL",Raw_Data!$L:$L,"IMPO",Raw_Data!$D:$D,M$1) -> 5 | N3: =SUMIFS(Raw_Data!$G:$G,Raw_Data!$C:$C,$K3,Raw_Data!$K:$K,2026,Raw_Data!$M:$M,"LCL",Raw_Data!$L:$L,"IMPO",Raw_Data!$D:$D,N$1) -> 2 | O3: =SUMIFS(Raw_Data!$G:$G,Raw_Data!$C:$C,$K3,Raw_Data!$K:$K,2026,Raw_Data!$M:$M,"LCL",Raw_Data!$L:$L,"IMPO",Raw_Data!$D:$D,O$1) -> 1 | P3: =SUMIFS(Raw_Data!$G:$G,Raw_Data!$C:$C,$K3,Raw_Data!$K:$K,2026,Raw_Data!$M:$M,"LCL",Raw_Data!$L:$L,"IMPO",Raw_Data!$D:$D,P$1) -> 4 | Q3: =SUMIFS(Raw_Data!$G:$G,Raw_Data!$C:$C,$K3,Raw_Data!$K:$K,2026,Raw_Data!$M:$M,"LCL",Raw_Data!$L:$L,"IMPO",Raw_Data!$D:$D,Q$1) -> 12 | R3: =SUMIFS(Raw_Data!$G:$G,Raw_Data!$C:$C,$K3,Raw_Data!$K:$K,2026,Raw_Data!$M:$M,"LCL",Raw_Data!$L:$L,"IMPO",Raw_Data!$D:$D,R$1) -> 114 | S3: =SUMIFS(Raw_Data!$G:$G,Raw_Data!$C:$C,$K3,Raw_Data!$K:$K,2026,Raw_Data!$M:$M,"LCL",Raw_Data!$L:$L,"IMPO",Raw_Data!$D:$D,S$1) -> 0 | U3: 16 | V3: =SUMIFS(Raw_Data!$J:$J,Raw_Data!$C:$C,$K3,Raw_Data!$K:$K,2026,Raw_Data!$M:$M,"LCL",Raw_Data!$L:$L,"IMPO",Raw_Data!$D:$D,V$1) -> 262.849 | W3: =SUMIFS(Raw_Data!$J:$J,Raw_Data!$C:$C,$K3,Raw_Data!$K:$K,2026,Raw_Data!$M:$M,"LCL",Raw_Data!$L:$L,"IMPO",Raw_Data!$D:$D,W$1) -> 10.755 | X3: =SUMIFS(Raw_Data!$J:$J,Raw_Data!$C:$C,$K3,Raw_Data!$K:$K,2026,Raw_Data!$M:$M,"LCL",Raw_Data!$L:$L,"IMPO",Raw_Data!$D:$D,X$1) -> 4.466 | Y3: =SUMIFS(Raw_Data!$J:$J,Raw_Data!$C:$C,$K3,Raw_Data!$K:$K,2026,Raw_Data!$M:$M,"LCL",Raw_Data!$L:$L,"IMPO",Raw_Data!$D:$D,Y$1) -> 5.849 | Z3: =SUMIFS(Raw_Data!$J:$J,Raw_Data!$C:$C,$K3,Raw_Data!$K:$K,2026,Raw_Data!$M:$M,"LCL",Raw_Data!$L:$L,"IMPO",Raw_Data!$D:$D,Z$1) -> 2.682 | AA3: =SUMIFS(Raw_Data!$J:$J,Raw_Data!$C:$C,$K3,Raw_Data!$K:$K,2026,Raw_Data!$M:$M,"LCL",Raw_Data!$L:$L,"IMPO",Raw_Data!$D:$D,AA$1) -> 24.08 | AB3: =SUMIFS(Raw_Data!$J:$J,Raw_Data!$C:$C,$K3,Raw_Data!$K:$K,2026,Raw_Data!$M:$M,"LCL",Raw_Data!$L:$L,"IMPO",Raw_Data!$D:$D,AB$1) -> 432.727 | AC3: =SUMIFS(Raw_Data!$J:$J,Raw_Data!$C:$C,$K3,Raw_Data!$K:$K,2026,Raw_Data!$M:$M,"LCL",Raw_Data!$L:$L,"IMPO",Raw_Data!$D:$D,AC$1) -> 0
A4: 16 | B4: =SUMIFS(Raw_Data!$G:$G,Raw_Data!$C:$C,$A4,Raw_Data!$K:$K,B$2,Raw_Data!$M:$M,"LCL",Raw_Data!$L:$L,"IMPO") -> 0 | C4: =SUMIFS(Raw_Data!$G:$G,Raw_Data!$C:$C,$A4,Raw_Data!$K:$K,C$2,Raw_Data!$M:$M,"LCL",Raw_Data!$L:$L,"IMPO") -> 206 | F4: 16 | G4: =SUMIFS(Raw_Data!$G:$G,Raw_Data!$C:$C,$F4,Raw_Data!$K:$K,G$2,Raw_Data!$M:$M,"LCL",Raw_Data!$L:$L,"EXPO") -> 0 | H4: =SUMIFS(Raw_Data!$G:$G,Raw_Data!$C:$C,$F4,Raw_Data!$K:$K,H$2,Raw_Data!$M:$M,"LCL",Raw_Data!$L:$L,"EXPO") -> 119 | K4: 17 | L4: =SUMIFS(Raw_Data!$G:$G,Raw_Data!$C:$C,$K4,Raw_Data!$K:$K,2026,Raw_Data!$M:$M,"LCL",Raw_Data!$L:$L,"IMPO",Raw_Data!$D:$D,L$1) -> 58 | M4: =SUMIFS(Raw_Data!$G:$G,Raw_Data!$C:$C,$K4,Raw_Data!$K:$K,2026,Raw_Data!$M:$M,"LCL",Raw_Data!$L:$L,"IMPO",Raw_Data!$D:$D,M$1) -> 12 | N4: =SUMIFS(Raw_Data!$G:$G,Raw_Data!$C:$C,$K4,Raw_Data!$K:$K,2026,Raw_Data!$M:$M,"LCL",Raw_Data!$L:$L,"IMPO",Raw_Data!$D:$D,N$1) -> 3 | O4: =SUMIFS(Raw_Data!$G:$G,Raw_Data!$C:$C,$K4,Raw_Data!$K:$K,2026,Raw_Data!$M:$M,"LCL",Raw_Data!$L:$L,"IMPO",Raw_Data!$D:$D,O$1) -> 1 | P4: =SUMIFS(Raw_Data!$G:$G,Raw_Data!$C:$C,$K4,Raw_Data!$K:$K,2026,Raw_Data!$M:$M,"LCL",Raw_Data!$L:$L,"IMPO",Raw_Data!$D:$D,P$1) -> 11 | Q4: =SUMIFS(Raw_Data!$G:$G,Raw_Data!$C:$C,$K4,Raw_Data!$K:$K,2026,Raw_Data!$M:$M,"LCL",Raw_Data!$L:$L,"IMPO",Raw_Data!$D:$D,Q$1) -> 7 | R4: =SUMIFS(Raw_Data!$G:$G,Raw_Data!$C:$C,$K4,Raw_Data!$K:$K,2026,Raw_Data!$M:$M,"LCL",Raw_Data!$L:$L,"IMPO",Raw_Data!$D:$D,R$1) -> 93 | S4: =SUMIFS(Raw_Data!$G:$G,Raw_Data!$C:$C,$K4,Raw_Data!$K:$K,2026,Raw_Data!$M:$M,"LCL",Raw_Data!$L:$L,"IMPO",Raw_Data!$D:$D,S$1) -> 0 | U4: 17 | V4: =SUMIFS(Raw_Data!$J:$J,Raw_Data!$C:$C,$K4,Raw_Data!$K:$K,2026,Raw_Data!$M:$M,"LCL",Raw_Data!$L:$L,"IMPO",Raw_Data!$D:$D,V$1) -> 237.805 | W4: =SUMIFS(Raw_Data!$J:$J,Raw_Data!$C:$C,$K4,Raw_Data!$K:$K,2026,Raw_Data!$M:$M,"LCL",Raw_Data!$L:$L,"IMPO",Raw_Data!$D:$D,W$1) -> 34.025 | X4: =SUMIFS(Raw_Data!$J:$J,Raw_Data!$C:$C,$K4,Raw_Data!$K:$K,2026,Raw_Data!$M:$M,"LCL",Raw_Data!$L:$L,"IMPO",Raw_Data!$D:$D,X$1) -> 8.162 | Y4: =SUMIFS(Raw_Data!$J:$J,Raw_Data!$C:$C,$K4,Raw_Data!$K:$K,2026,Raw_Data!$M:$M,"LCL",Raw_Data!$L:$L,"IMPO",Raw_Data!$D:$D,Y$1) -> 1.71 | Z4: =SUMIFS(Raw_Data!$J:$J,Raw_Data!$C:$C,$K4,Raw_Data!$K:$K,2026,Raw_Data!$M:$M,"LCL",Raw_Data!$L:$L,"IMPO",Raw_Data!$D:$D,Z$1) -> 27.464 | AA4: =SUMIFS(Raw_Data!$J:$J,Raw_Data!$C:$C,$K4,Raw_Data!$K:$K,2026,Raw_Data!$M:$M,"LCL",Raw_Data!$L:$L,"IMPO",Raw_Data!$D:$D,AA$1) -> 33.141 | AB4: =SUMIFS(Raw_Data!$J:$J,Raw_Data!$C:$C,$K4,Raw_Data!$K:$K,2026,Raw_Data!$M:$M,"LCL",Raw_Data!$L:$L,"IMPO",Raw_Data!$D:$D,AB$1) -> 384.09 | AC4: =SUMIFS(Raw_Data!$J:$J,Raw_Data!$C:$C,$K4,Raw_Data!$K:$K,2026,Raw_Data!$M:$M,"LCL",Raw_Data!$L:$L,"IMPO",Raw_Data!$D:$D,AC$1) -> 0
A5: 17 | B5: =SUMIFS(Raw_Data!$G:$G,Raw_Data!$C:$C,$A5,Raw_Data!$K:$K,B$2,Raw_Data!$M:$M,"LCL",Raw_Data!$L:$L,"IMPO") -> 0 | C5: =SUMIFS(Raw_Data!$G:$G,Raw_Data!$C:$C,$A5,Raw_Data!$K:$K,C$2,Raw_Data!$M:$M,"LCL",Raw_Data!$L:$L,"IMPO") -> 185 | F5: 17 | G5: =SUMIFS(Raw_Data!$G:$G,Raw_Data!$C:$C,$F5,Raw_Data!$K:$K,G$2,Raw_Data!$M:$M,"LCL",Raw_Data!$L:$L,"EXPO") -> 0 | H5: =SUMIFS(Raw_Data!$G:$G,Raw_Data!$C:$C,$F5,Raw_Data!$K:$K,H$2,Raw_Data!$M:$M,"LCL",Raw_Data!$L:$L,"EXPO") -> 108 | K5: 18 | L5: =SUMIFS(Raw_Data!$G:$G,Raw_Data!$C:$C,$K5,Raw_Data!$K:$K,2026,Raw_Data!$M:$M,"LCL",Raw_Data!$L:$L,"IMPO",Raw_Data!$D:$D,L$1) -> 102 | M5: =SUMIFS(Raw_Data!$G:$G,Raw_Data!$C:$C,$K5,Raw_Data!$K:$K,2026,Raw_Data!$M:$M,"LCL",Raw_Data!$L:$L,"IMPO",Raw_Data!$D:$D,M$1) -> 18 | N5: =SUMIFS(Raw_Data!$G:$G,Raw_Data!$C:$C,$K5,Raw_Data!$K:$K,2026,Raw_Data!$M:$M,"LCL",Raw_Data!$L:$L,"IMPO",Raw_Data!$D:$D,N$1) -> 7 | O5: =SUMIFS(Raw_Data!$G:$G,Raw_Data!$C:$C,$K5,Raw_Data!$K:$K,2026,Raw_Data!$M:$M,"LCL",Raw_Data!$L:$L,"IMPO",Raw_Data!$D:$D,O$1) -> 7 | P5: =SUMIFS(Raw_Data!$G:$G,Raw_Data!$C:$C,$K5,Raw_Data!$K:$K,2026,Raw_Data!$M:$M,"LCL",Raw_Data!$L:$L,"IMPO",Raw_Data!$D:$D,P$1) -> 18 | Q5: =SUMIFS(Raw_Data!$G:$G,Raw_Data!$C:$C,$K5,Raw_Data!$K:$K,2026,Raw_Data!$M:$M,"LCL",Raw_Data!$L:$L,"IMPO",Raw_Data!$D:$D,Q$1) -> 13 | R5: =SUMIFS(Raw_Data!$G:$G,Raw_Data!$C:$C,$K5,Raw_Data!$K:$K,2026,Raw_Data!$M:$M,"LCL",Raw_Data!$L:$L,"IMPO",Raw_Data!$D:$D,R$1) -> 162 | S5: =SUMIFS(Raw_Data!$G:$G,Raw_Data!$C:$C,$K5,Raw_Data!$K:$K,2026,Raw_Data!$M:$M,"LCL",Raw_Data!$L:$L,"IMPO",Raw_Data!$D:$D,S$1) -> 0 | U5: 18 | V5: =SUMIFS(Raw_Data!$J:$J,Raw_Data!$C:$C,$K5,Raw_Data!$K:$K,2026,Raw_Data!$M:$M,"LCL",Raw_Data!$L:$L,"IMPO",Raw_Data!$D:$D,V$1) -> 342.892 | W5: =SUMIFS(Raw_Data!$J:$J,Raw_Data!$C:$C,$K5,Raw_Data!$K:$K,2026,Raw_Data!$M:$M,"LCL",Raw_Data!$L:$L,"IMPO",Raw_Data!$D:$D,W$1) -> 72.937 | X5: =SUMIFS(Raw_Data!$J:$J,Raw_Data!$C:$C,$K5,Raw_Data!$K:$K,2026,Raw_Data!$M:$M,"LCL",Raw_Data!$L:$L,"IMPO",Raw_Data!$D:$D,X$1) -> 15.823 | Y5: =SUMIFS(Raw_Data!$J:$J,Raw_Data!$C:$C,$K5,Raw_Data!$K:$K,2026,Raw_Data!$M:$M,"LCL",Raw_Data!$L:$L,"IMPO",Raw_Data!$D:$D,Y$1) -> 24.959 | Z5: =SUMIFS(Raw_Data!$J:$J,Raw_Data!$C:$C,$K5,Raw_Data!$K:$K,2026,Raw_Data!$M:$M,"LCL",Raw_Data!$L:$L,"IMPO",Raw_Data!$D:$D,Z$1) -> 66.132 | AA5: =SUMIFS(Raw_Data!$J:$J,Raw_Data!$C:$C,$K5,Raw_Data!$K:$K,2026,Raw_Data!$M:$M,"LCL",Raw_Data!$L:$L,"IMPO",Raw_Data!$D:$D,AA$1) -> 43.374 | AB5: =SUMIFS(Raw_Data!$J:$J,Raw_Data!$C:$C,$K5,Raw_Data!$K:$K,2026,Raw_Data!$M:$M,"LCL",Raw_Data!$L:$L,"IMPO",Raw_Data!$D:$D,AB$1) -> 652.098 | AC5: =SUMIFS(Raw_Data!$J:$J,Raw_Data!$C:$C,$K5,Raw_Data!$K:$K,2026,Raw_Data!$M:$M,"LCL",Raw_Data!$L:$L,"IMPO",Raw_Data!$D:$D,AC$1) -> 0
A6: 18 | B6: =SUMIFS(Raw_Data!$G:$G,Raw_Data!$C:$C,$A6,Raw_Data!$K:$K,B$2,Raw_Data!$M:$M,"LCL",Raw_Data!$L:$L,"IMPO") -> 0 | C6: =SUMIFS(Raw_Data!$G:$G,Raw_Data!$C:$C,$A6,Raw_Data!$K:$K,C$2,Raw_Data!$M:$M,"LCL",Raw_Data!$L:$L,"IMPO") -> 327 | F6: 18 | G6: =SUMIFS(Raw_Data!$G:$G,Raw_Data!$C:$C,$F6,Raw_Data!$K:$K,G$2,Raw_Data!$M:$M,"LCL",Raw_Data!$L:$L,"EXPO") -> 0 | H6: =SUMIFS(Raw_Data!$G:$G,Raw_Data!$C:$C,$F6,Raw_Data!$K:$K,H$2,Raw_Data!$M:$M,"LCL",Raw_Data!$L:$L,"EXPO") -> 92 | K6: 19 | L6: =SUMIFS(Raw_Data!$G:$G,Raw_Data!$C:$C,$K6,Raw_Data!$K:$K,2026,Raw_Data!$M:$M,"LCL",Raw_Data!$L:$L,"IMPO",Raw_Data!$D:$D,L$1) -> 79 | M6: =SUMIFS(Raw_Data!$G:$G,Raw_Data!$C:$C,$K6,Raw_Data!$K:$K,2026,Raw_Data!$M:$M,"LCL",Raw_Data!$L:$L,"IMPO",Raw_Data!$D:$D,M$1) -> 13 | N6: =SUMIFS(Raw_Data!$G:$G,Raw_Data!$C:$C,$K6,Raw_Data!$K:$K,2026,Raw_Data!$M:$M,"LCL",Raw_Data!$L:$L,"IMPO",Raw_Data!$D:$D,N$1) -> 0 | O6: =SUMIFS(Raw_Data!$G:$G,Raw_Data!$C:$C,$K6,Raw_Data!$K:$K,2026,Raw_Data!$M:$M,"LCL",Raw_Data!$L:$L,"IMPO",Raw_Data!$D:$D,O$1) -> 2 | P6: =SUMIFS(Raw_Data!$G:$G,Raw_Data!$C:$C,$K6,Raw_Data!$K:$K,2026,Raw_Data!$M:$M,"LCL",Raw_Data!$L:$L,"IMPO",Raw_Data!$D:$D,P$1) -> 8 | Q6: =SUMIFS(Raw_Data!$G:$G,Raw_Data!$C:$C,$K6,Raw_Data!$K:$K,2026,Raw_Data!$M:$M,"LCL",Raw_Data!$L:$L,"IMPO",Raw_Data!$D:$D,Q$1) -> 8 | R6: =SUMIFS(Raw_Data!$G:$G,Raw_Data!$C:$C,$K6,Raw_Data!$K:$K,2026,Raw_Data!$M:$M,"LCL",Raw_Data!$L:$L,"IMPO",Raw_Data!$D:$D,R$1) -> 107 | S6: =SUMIFS(Raw_Data!$G:$G,Raw_Data!$C:$C,$K6,Raw_Data!$K:$K,2026,Raw_Data!$M:$M,"LCL",Raw_Data!$L:$L,"IMPO",Raw_Data!$D:$D,S$1) -> 0 | U6: 19 | V6: =SUMIFS(Raw_Data!$J:$J,Raw_Data!$C:$C,$K6,Raw_Data!$K:$K,2026,Raw_Data!$M:$M,"LCL",Raw_Data!$L:$L,"IMPO",Raw_Data!$D:$D,V$1) -> 326.495 | W6: =SUMIFS(Raw_Data!$J:$J,Raw_Data!$C:$C,$K6,Raw_Data!$K:$K,2026,Raw_Data!$M:$M,"LCL",Raw_Data!$L:$L,"IMPO",Raw_Data!$D:$D,W$1) -> 49.116 | X6: =SUMIFS(Raw_Data!$J:$J,Raw_Data!$C:$C,$K6,Raw_Data!$K:$K,2026,Raw_Data!$M:$M,"LCL",Raw_Data!$L:$L,"IMPO",Raw_Data!$D:$D,X$1) -> 0 | Y6: =SUMIFS(Raw_Data!$J:$J,Raw_Data!$C:$C,$K6,Raw_Data!$K:$K,2026,Raw_Data!$M:$M,"LCL",Raw_Data!$L:$L,"IMPO",Raw_Data!$D:$D,Y$1) -> 3.402 | Z6: =SUMIFS(Raw_Data!$J:$J,Raw_Data!$C:$C,$K6,Raw_Data!$K:$K,2026,Raw_Data!$M:$M,"LCL",Raw_Data!$L:$L,"IMPO",Raw_Data!$D:$D,Z$1) -> 46.247 | AA6: =SUMIFS(Raw_Data!$J:$J,Raw_Data!$C:$C,$K6,Raw_Data!$K:$K,2026,Raw_Data!$M:$M,"LCL",Raw_Data!$L:$L,"IMPO",Raw_Data!$D:$D,AA$1) -> 18.189 | AB6: =SUMIFS(Raw_Data!$J:$J,Raw_Data!$C:$C,$K6,Raw_Data!$K:$K,2026,Raw_Data!$M:$M,"LCL",Raw_Data!$L:$L,"IMPO",Raw_Data!$D:$D,AB$1) -> 424.58 | AC6: =SUMIFS(Raw_Data!$J:$J,Raw_Data!$C:$C,$K6,Raw_Data!$K:$K,2026,Raw_Data!$M:$M,"LCL",Raw_Data!$L:$L,"IMPO",Raw_Data!$D:$D,AC$1) -> 0
A7: 19 | B7: =SUMIFS(Raw_Data!$G:$G,Raw_Data!$C:$C,$A7,Raw_Data!$K:$K,B$2,Raw_Data!$M:$M,"LCL",Raw_Data!$L:$L,"IMPO") -> 0 | C7: =SUMIFS(Raw_Data!$G:$G,Raw_Data!$C:$C,$A7,Raw_Data!$K:$K,C$2,Raw_Data!$M:$M,"LCL",Raw_Data!$L:$L,"IMPO") -> 217 | F7: 19 | G7: =SUMIFS(Raw_Data!$G:$G,Raw_Data!$C:$C,$F7,Raw_Data!$K:$K,G$2,Raw_Data!$M:$M,"LCL",Raw_Data!$L:$L,"EXPO") -> 0 | H7: =SUMIFS(Raw_Data!$G:$G,Raw_Data!$C:$C,$F7,Raw_Data!$K:$K,H$2,Raw_Data!$M:$M,"LCL",Raw_Data!$L:$L,"EXPO") -> 84 | K7: 20 | L7: =SUMIFS(Raw_Data!$G:$G,Raw_Data!$C:$C,$K7,Raw_Data!$K:$K,2026,Raw_Data!$M:$M,"LCL",Raw_Data!$L:$L,"IMPO",Raw_Data!$D:$D,L$1) -> 50 | M7: =SUMIFS(Raw_Data!$G:$G,Raw_Data!$C:$C,$K7,Raw_Data!$K:$K,2026,Raw_Data!$M:$M,"LCL",Raw_Data!$L:$L,"IMPO",Raw_Data!$D:$D,M$1) -> 11 | N7: =SUMIFS(Raw_Data!$G:$G,Raw_Data!$C:$C,$K7,Raw_Data!$K:$K,2026,Raw_Data!$M:$M,"LCL",Raw_Data!$L:$L,"IMPO",Raw_Data!$D:$D,N$1) -> 4 | O7: =SUMIFS(Raw_Data!$G:$G,Raw_Data!$C:$C,$K7,Raw_Data!$K:$K,2026,Raw_Data!$M:$M,"LCL",Raw_Data!$L:$L,"IMPO",Raw_Data!$D:$D,O$1) -> 1 | P7: =SUMIFS(Raw_Data!$G:$G,Raw_Data!$C:$C,$K7,Raw_Data!$K:$K,2026,Raw_Data!$M:$M,"LCL",Raw_Data!$L:$L,"IMPO",Raw_Data!$D:$D,P$1) -> 3 | Q7: =SUMIFS(Raw_Data!$G:$G,Raw_Data!$C:$C,$K7,Raw_Data!$K:$K,2026,Raw_Data!$M:$M,"LCL",Raw_Data!$L:$L,"IMPO",Raw_Data!$D:$D,Q$1) -> 12 | R7: =SUMIFS(Raw_Data!$G:$G,Raw_Data!$C:$C,$K7,Raw_Data!$K:$K,2026,Raw_Data!$M:$M,"LCL",Raw_Data!$L:$L,"IMPO",Raw_Data!$D:$D,R$1) -> 66 | S7: =SUMIFS(Raw_Data!$G:$G,Raw_Data!$C:$C,$K7,Raw_Data!$K:$K,2026,Raw_Data!$M:$M,"LCL",Raw_Data!$L:$L,"IMPO",Raw_Data!$D:$D,S$1) -> 0 | U7: 20 | V7: =SUMIFS(Raw_Data!$J:$J,Raw_Data!$C:$C,$K7,Raw_Data!$K:$K,2026,Raw_Data!$M:$M,"LCL",Raw_Data!$L:$L,"IMPO",Raw_Data!$D:$D,V$1) -> 234.06 | W7: =SUMIFS(Raw_Data!$J:$J,Raw_Data!$C:$C,$K7,Raw_Data!$K:$K,2026,Raw_Data!$M:$M,"LCL",Raw_Data!$L:$L,"IMPO",Raw_Data!$D:$D,W$1) -> 54.914 | X7: =SUMIFS(Raw_Data!$J:$J,Raw_Data!$C:$C,$K7,Raw_Data!$K:$K,2026,Raw_Data!$M:$M,"LCL",Raw_Data!$L:$L,"IMPO",Raw_Data!$D:$D,X$1) -> 14.365 | Y7: =SUMIFS(Raw_Data!$J:$J,Raw_Data!$C:$C,$K7,Raw_Data!$K:$K,2026,Raw_Data!$M:$M,"LCL",Raw_Data!$L:$L,"IMPO",Raw_Data!$D:$D,Y$1) -> 1.308 | Z7: =SUMIFS(Raw_Data!$J:$J,Raw_Data!$C:$C,$K7,Raw_Data!$K:$K,2026,Raw_Data!$M:$M,"LCL",Raw_Data!$L:$L,"IMPO",Raw_Data!$D:$D,Z$1) -> 1.373 | AA7: =SUMIFS(Raw_Data!$J:$J,Raw_Data!$C:$C,$K7,Raw_Data!$K:$K,2026,Raw_Data!$M:$M,"LCL",Raw_Data!$L:$L,"IMPO",Raw_Data!$D:$D,AA$1) -> 19.021 | AB7: =SUMIFS(Raw_Data!$J:$J,Raw_Data!$C:$C,$K7,Raw_Data!$K:$K,2026,Raw_Data!$M:$M,"LCL",Raw_Data!$L:$L,"IMPO",Raw_Data!$D:$D,AB$1) -> 299.167 | AC7: =SUMIFS(Raw_Data!$J:$J,Raw_Data!$C:$C,$K7,Raw_Data!$K:$K,2026,Raw_Data!$M:$M,"LCL",Raw_Data!$L:$L,"IMPO",Raw_Data!$D:$D,AC$1) -> 0
A8: 20 | B8: =SUMIFS(Raw_Data!$G:$G,Raw_Data!$C:$C,$A8,Raw_Data!$K:$K,B$2,Raw_Data!$M:$M,"LCL",Raw_Data!$L:$L,"IMPO") -> 0 | C8: =SUMIFS(Raw_Data!$G:$G,Raw_Data!$C:$C,$A8,Raw_Data!$K:$K,C$2,Raw_Data!$M:$M,"LCL",Raw_Data!$L:$L,"IMPO") -> 149 | F8: 20 | G8: =SUMIFS(Raw_Data!$G:$G,Raw_Data!$C:$C,$F8,Raw_Data!$K:$K,G$2,Raw_Data!$M:$M,"LCL",Raw_Data!$L:$L,"EXPO") -> 0 | H8: =SUMIFS(Raw_Data!$G:$G,Raw_Data!$C:$C,$F8,Raw_Data!$K:$K,H$2,Raw_Data!$M:$M,"LCL",Raw_Data!$L:$L,"EXPO") -> 113 | K8: 21 | L8: =SUMIFS(Raw_Data!$G:$G,Raw_Data!$C:$C,$K8,Raw_Data!$K:$K,2026,Raw_Data!$M:$M,"LCL",Raw_Data!$L:$L,"IMPO",Raw_Data!$D:$D,L$1) -> 0 | M8: =SUMIFS(Raw_Data!$G:$G,Raw_Data!$C:$C,$K8,Raw_Data!$K:$K,2026,Raw_Data!$M:$M,"LCL",Raw_Data!$L:$L,"IMPO",Raw_Data!$D:$D,M$1) -> 0 | N8: =SUMIFS(Raw_Data!$G:$G,Raw_Data!$C:$C,$K8,Raw_Data!$K:$K,2026,Raw_Data!$M:$M,"LCL",Raw_Data!$L:$L,"IMPO",Raw_Data!$D:$D,N$1) -> 0 | O8: =SUMIFS(Raw_Data!$G:$G,Raw_Data!$C:$C,$K8,Raw_Data!$K:$K,2026,Raw_Data!$M:$M,"LCL",Raw_Data!$L:$L,"IMPO",Raw_Data!$D:$D,O$1) -> 0 | P8: =SUMIFS(Raw_Data!$G:$G,Raw_Data!$C:$C,$K8,Raw_Data!$K:$K,2026,Raw_Data!$M:$M,"LCL",Raw_Data!$L:$L,"IMPO",Raw_Data!$D:$D,P$1) -> 0 | Q8: =SUMIFS(Raw_Data!$G:$G,Raw_Data!$C:$C,$K8,Raw_Data!$K:$K,2026,Raw_Data!$M:$M,"LCL",Raw_Data!$L:$L,"IMPO",Raw_Data!$D:$D,Q$1) -> 0 | R8: =SUMIFS(Raw_Data!$G:$G,Raw_Data!$C:$C,$K8,Raw_Data!$K:$K,2026,Raw_Data!$M:$M,"LCL",Raw_Data!$L:$L,"IMPO",Raw_Data!$D:$D,R$1) -> 0 | S8: =SUMIFS(Raw_Data!$G:$G,Raw_Data!$C:$C,$K8,Raw_Data!$K:$K,2026,Raw_Data!$M:$M,"LCL",Raw_Data!$L:$L,"IMPO",Raw_Data!$D:$D,S$1) -> 0 | U8: 21 | V8: =SUMIFS(Raw_Data!$J:$J,Raw_Data!$C:$C,$K8,Raw_Data!$K:$K,2026,Raw_Data!$M:$M,"LCL",Raw_Data!$L:$L,"IMPO",Raw_Data!$D:$D,V$1) -> 0 | W8: =SUMIFS(Raw_Data!$J:$J,Raw_Data!$C:$C,$K8,Raw_Data!$K:$K,2026,Raw_Data!$M:$M,"LCL",Raw_Data!$L:$L,"IMPO",Raw_Data!$D:$D,W$1) -> 0 | X8: =SUMIFS(Raw_Data!$J:$J,Raw_Data!$C:$C,$K8,Raw_Data!$K:$K,2026,Raw_Data!$M:$M,"LCL",Raw_Data!$L:$L,"IMPO",Raw_Data!$D:$D,X$1) -> 0 | Y8: =SUMIFS(Raw_Data!$J:$J,Raw_Data!$C:$C,$K8,Raw_Data!$K:$K,2026,Raw_Data!$M:$M,"LCL",Raw_Data!$L:$L,"IMPO",Raw_Data!$D:$D,Y$1) -> 0 | Z8: =SUMIFS(Raw_Data!$J:$J,Raw_Data!$C:$C,$K8,Raw_Data!$K:$K,2026,Raw_Data!$M:$M,"LCL",Raw_Data!$L:$L,"IMPO",Raw_Data!$D:$D,Z$1) -> 0 | AA8: =SUMIFS(Raw_Data!$J:$J,Raw_Data!$C:$C,$K8,Raw_Data!$K:$K,2026,Raw_Data!$M:$M,"LCL",Raw_Data!$L:$L,"IMPO",Raw_Data!$D:$D,AA$1) -> 0 | AB8: =SUMIFS(Raw_Data!$J:$J,Raw_Data!$C:$C,$K8,Raw_Data!$K:$K,2026,Raw_Data!$M:$M,"LCL",Raw_Data!$L:$L,"IMPO",Raw_Data!$D:$D,AB$1) -> 0 | AC8: =SUMIFS(Raw_Data!$J:$J,Raw_Data!$C:$C,$K8,Raw_Data!$K:$K,2026,Raw_Data!$M:$M,"LCL",Raw_Data!$L:$L,"IMPO",Raw_Data!$D:$D,AC$1) -> 0
A9: 21 | B9: =SUMIFS(Raw_Data!$G:$G,Raw_Data!$C:$C,$A9,Raw_Data!$K:$K,B$2,Raw_Data!$M:$M,"LCL",Raw_Data!$L:$L,"IMPO") -> 0 | C9: =SUMIFS(Raw_Data!$G:$G,Raw_Data!$C:$C,$A9,Raw_Data!$K:$K,C$2,Raw_Data!$M:$M,"LCL",Raw_Data!$L:$L,"IMPO") -> 0 | F9: 21 | G9: =SUMIFS(Raw_Data!$G:$G,Raw_Data!$C:$C,$F9,Raw_Data!$K:$K,G$2,Raw_Data!$M:$M,"LCL",Raw_Data!$L:$L,"EXPO") -> 0 | H9: =SUMIFS(Raw_Data!$G:$G,Raw_Data!$C:$C,$F9,Raw_Data!$K:$K,H$2,Raw_Data!$M:$M,"LCL",Raw_Data!$L:$L,"EXPO") -> 0 | K9: 22 | L9: =SUMIFS(Raw_Data!$G:$G,Raw_Data!$C:$C,$K9,Raw_Data!$K:$K,2026,Raw_Data!$M:$M,"LCL",Raw_Data!$L:$L,"IMPO",Raw_Data!$D:$D,L$1) -> 0 | M9: =SUMIFS(Raw_Data!$G:$G,Raw_Data!$C:$C,$K9,Raw_Data!$K:$K,2026,Raw_Data!$M:$M,"LCL",Raw_Data!$L:$L,"IMPO",Raw_Data!$D:$D,M$1) -> 0 | N9: =SUMIFS(Raw_Data!$G:$G,Raw_Data!$C:$C,$K9,Raw_Data!$K:$K,2026,Raw_Data!$M:$M,"LCL",Raw_Data!$L:$L,"IMPO",Raw_Data!$D:$D,N$1) -> 0 | O9: =SUMIFS(Raw_Data!$G:$G,Raw_Data!$C:$C,$K9,Raw_Data!$K:$K,2026,Raw_Data!$M:$M,"LCL",Raw_Data!$L:$L,"IMPO",Raw_Data!$D:$D,O$1) -> 0 | P9: =SUMIFS(Raw_Data!$G:$G,Raw_Data!$C:$C,$K9,Raw_Data!$K:$K,2026,Raw_Data!$M:$M,"LCL",Raw_Data!$L:$L,"IMPO",Raw_Data!$D:$D,P$1) -> 0 | Q9: =SUMIFS(Raw_Data!$G:$G,Raw_Data!$C:$C,$K9,Raw_Data!$K:$K,2026,Raw_Data!$M:$M,"LCL",Raw_Data!$L:$L,"IMPO",Raw_Data!$D:$D,Q$1) -> 0 | R9: =SUMIFS(Raw_Data!$G:$G,Raw_Data!$C:$C,$K9,Raw_Data!$K:$K,2026,Raw_Data!$M:$M,"LCL",Raw_Data!$L:$L,"IMPO",Raw_Data!$D:$D,R$1) -> 0 | S9: =SUMIFS(Raw_Data!$G:$G,Raw_Data!$C:$C,$K9,Raw_Data!$K:$K,2026,Raw_Data!$M:$M,"LCL",Raw_Data!$L:$L,"IMPO",Raw_Data!$D:$D,S$1) -> 0 | U9: 22 | V9: =SUMIFS(Raw_Data!$J:$J,Raw_Data!$C:$C,$K9,Raw_Data!$K:$K,2026,Raw_Data!$M:$M,"LCL",Raw_Data!$L:$L,"IMPO",Raw_Data!$D:$D,V$1) -> 0 | W9: =SUMIFS(Raw_Data!$J:$J,Raw_Data!$C:$C,$K9,Raw_Data!$K:$K,2026,Raw_Data!$M:$M,"LCL",Raw_Data!$L:$L,"IMPO",Raw_Data!$D:$D,W$1) -> 0 | X9: =SUMIFS(Raw_Data!$J:$J,Raw_Data!$C:$C,$K9,Raw_Data!$K:$K,2026,Raw_Data!$M:$M,"LCL",Raw_Data!$L:$L,"IMPO",Raw_Data!$D:$D,X$1) -> 0 | Y9: =SUMIFS(Raw_Data!$J:$J,Raw_Data!$C:$C,$K9,Raw_Data!$K:$K,2026,Raw_Data!$M:$M,"LCL",Raw_Data!$L:$L,"IMPO",Raw_Data!$D:$D,Y$1) -> 0 | Z9: =SUMIFS(Raw_Data!$J:$J,Raw_Data!$C:$C,$K9,Raw_Data!$K:$K,2026,Raw_Data!$M:$M,"LCL",Raw_Data!$L:$L,"IMPO",Raw_Data!$D:$D,Z$1) -> 0 | AA9: =SUMIFS(Raw_Data!$J:$J,Raw_Data!$C:$C,$K9,Raw_Data!$K:$K,2026,Raw_Data!$M:$M,"LCL",Raw_Data!$L:$L,"IMPO",Raw_Data!$D:$D,AA$1) -> 0 | AB9: =SUMIFS(Raw_Data!$J:$J,Raw_Data!$C:$C,$K9,Raw_Data!$K:$K,2026,Raw_Data!$M:$M,"LCL",Raw_Data!$L:$L,"IMPO",Raw_Data!$D:$D,AB$1) -> 0 | AC9: =SUMIFS(Raw_Data!$J:$J,Raw_Data!$C:$C,$K9,Raw_Data!$K:$K,2026,Raw_Data!$M:$M,"LCL",Raw_Data!$L:$L,"IMPO",Raw_Data!$D:$D,AC$1) -> 0
A10: 22 | B10: =SUMIFS(Raw_Data!$G:$G,Raw_Data!$C:$C,$A10,Raw_Data!$K:$K,B$2,Raw_Data!$M:$M,"LCL",Raw_Data!$L:$L,"IMPO") -> 0 | C10: =SUMIFS(Raw_Data!$G:$G,Raw_Data!$C:$C,$A10,Raw_Data!$K:$K,C$2,Raw_Data!$M:$M,"LCL",Raw_Data!$L:$L,"IMPO") -> 0 | F10: 22 | G10: =SUMIFS(Raw_Data!$G:$G,Raw_Data!$C:$C,$F10,Raw_Data!$K:$K,G$2,Raw_Data!$M:$M,"LCL",Raw_Data!$L:$L,"EXPO") -> 0 | H10: =SUMIFS(Raw_Data!$G:$G,Raw_Data!$C:$C,$F10,Raw_Data!$K:$K,H$2,Raw_Data!$M:$M,"LCL",Raw_Data!$L:$L,"EXPO") -> 0 | K10: 23 | L10: =SUMIFS(Raw_Data!$G:$G,Raw_Data!$C:$C,$K10,Raw_Data!$K:$K,2026,Raw_Data!$M:$M,"LCL",Raw_Data!$L:$L,"IMPO",Raw_Data!$D:$D,L$1) -> 0 | M10: =SUMIFS(Raw_Data!$G:$G,Raw_Data!$C:$C,$K10,Raw_Data!$K:$K,2026,Raw_Data!$M:$M,"LCL",Raw_Data!$L:$L,"IMPO",Raw_Data!$D:$D,M$1) -> 0 | N10: =SUMIFS(Raw_Data!$G:$G,Raw_Data!$C:$C,$K10,Raw_Data!$K:$K,2026,Raw_Data!$M:$M,"LCL",Raw_Data!$L:$L,"IMPO",Raw_Data!$D:$D,N$1) -> 0 | O10: =SUMIFS(Raw_Data!$G:$G,Raw_Data!$C:$C,$K10,Raw_Data!$K:$K,2026,Raw_Data!$M:$M,"LCL",Raw_Data!$L:$L,"IMPO",Raw_Data!$D:$D,O$1) -> 0 | P10: =SUMIFS(Raw_Data!$G:$G,Raw_Data!$C:$C,$K10,Raw_Data!$K:$K,2026,Raw_Data!$M:$M,"LCL",Raw_Data!$L:$L,"IMPO",Raw_Data!$D:$D,P$1) -> 0 | Q10: =SUMIFS(Raw_Data!$G:$G,Raw_Data!$C:$C,$K10,Raw_Data!$K:$K,2026,Raw_Data!$M:$M,"LCL",Raw_Data!$L:$L,"IMPO",Raw_Data!$D:$D,Q$1) -> 0 | R10: =SUMIFS(Raw_Data!$G:$G,Raw_Data!$C:$C,$K10,Raw_Data!$K:$K,2026,Raw_Data!$M:$M,"LCL",Raw_Data!$L:$L,"IMPO",Raw_Data!$D:$D,R$1) -> 0 | S10: =SUMIFS(Raw_Data!$G:$G,Raw_Data!$C:$C,$K10,Raw_Data!$K:$K,2026,Raw_Data!$M:$M,"LCL",Raw_Data!$L:$L,"IMPO",Raw_Data!$D:$D,S$1) -> 0 | U10: 23 | V10: =SUMIFS(Raw_Data!$J:$J,Raw_Data!$C:$C,$K10,Raw_Data!$K:$K,2026,Raw_Data!$M:$M,"LCL",Raw_Data!$L:$L,"IMPO",Raw_Data!$D:$D,V$1) -> 0 | W10: =SUMIFS(Raw_Data!$J:$J,Raw_Data!$C:$C,$K10,Raw_Data!$K:$K,2026,Raw_Data!$M:$M,"LCL",Raw_Data!$L:$L,"IMPO",Raw_Data!$D:$D,W$1) -> 0 | X10: =SUMIFS(Raw_Data!$J:$J,Raw_Data!$C:$C,$K10,Raw_Data!$K:$K,2026,Raw_Data!$M:$M,"LCL",Raw_Data!$L:$L,"IMPO",Raw_Data!$D:$D,X$1) -> 0 | Y10: =SUMIFS(Raw_Data!$J:$J,Raw_Data!$C:$C,$K10,Raw_Data!$K:$K,2026,Raw_Data!$M:$M,"LCL",Raw_Data!$L:$L,"IMPO",Raw_Data!$D:$D,Y$1) -> 0 | Z10: =SUMIFS(Raw_Data!$J:$J,Raw_Data!$C:$C,$K10,Raw_Data!$K:$K,2026,Raw_Data!$M:$M,"LCL",Raw_Data!$L:$L,"IMPO",Raw_Data!$D:$D,Z$1) -> 0 | AA10: =SUMIFS(Raw_Data!$J:$J,Raw_Data!$C:$C,$K10,Raw_Data!$K:$K,2026,Raw_Data!$M:$M,"LCL",Raw_Data!$L:$L,"IMPO",Raw_Data!$D:$D,AA$1) -> 0 | AB10: =SUMIFS(Raw_Data!$J:$J,Raw_Data!$C:$C,$K10,Raw_Data!$K:$K,2026,Raw_Data!$M:$M,"LCL",Raw_Data!$L:$L,"IMPO",Raw_Data!$D:$D,AB$1) -> 0 | AC10: =SUMIFS(Raw_Data!$J:$J,Raw_Data!$C:$C,$K10,Raw_Data!$K:$K,2026,Raw_Data!$M:$M,"LCL",Raw_Data!$L:$L,"IMPO",Raw_Data!$D:$D,AC$1) -> 0
A11: 23 | B11: =SUMIFS(Raw_Data!$G:$G,Raw_Data!$C:$C,$A11,Raw_Data!$K:$K,B$2,Raw_Data!$M:$M,"LCL",Raw_Data!$L:$L,"IMPO") -> 0 | C11: =SUMIFS(Raw_Data!$G:$G,Raw_Data!$C:$C,$A11,Raw_Data!$K:$K,C$2,Raw_Data!$M:$M,"LCL",Raw_Data!$L:$L,"IMPO") -> 0 | F11: 23 | G11: =SUMIFS(Raw_Data!$G:$G,Raw_Data!$C:$C,$F11,Raw_Data!$K:$K,G$2,Raw_Data!$M:$M,"LCL",Raw_Data!$L:$L,"EXPO") -> 0 | H11: =SUMIFS(Raw_Data!$G:$G,Raw_Data!$C:$C,$F11,Raw_Data!$K:$K,H$2,Raw_Data!$M:$M,"LCL",Raw_Data!$L:$L,"EXPO") -> 0 | K11: 24 | L11: =SUMIFS(Raw_Data!$G:$G,Raw_Data!$C:$C,$K11,Raw_Data!$K:$K,2026,Raw_Data!$M:$M,"LCL",Raw_Data!$L:$L,"IMPO",Raw_Data!$D:$D,L$1) -> 0 | M11: =SUMIFS(Raw_Data!$G:$G,Raw_Data!$C:$C,$K11,Raw_Data!$K:$K,2026,Raw_Data!$M:$M,"LCL",Raw_Data!$L:$L,"IMPO",Raw_Data!$D:$D,M$1) -> 0 | N11: =SUMIFS(Raw_Data!$G:$G,Raw_Data!$C:$C,$K11,Raw_Data!$K:$K,2026,Raw_Data!$M:$M,"LCL",Raw_Data!$L:$L,"IMPO",Raw_Data!$D:$D,N$1) -> 0 | O11: =SUMIFS(Raw_Data!$G:$G,Raw_Data!$C:$C,$K11,Raw_Data!$K:$K,2026,Raw_Data!$M:$M,"LCL",Raw_Data!$L:$L,"IMPO",Raw_Data!$D:$D,O$1) -> 0 | P11: =SUMIFS(Raw_Data!$G:$G,Raw_Data!$C:$C,$K11,Raw_Data!$K:$K,2026,Raw_Data!$M:$M,"LCL",Raw_Data!$L:$L,"IMPO",Raw_Data!$D:$D,P$1) -> 0 | Q11: =SUMIFS(Raw_Data!$G:$G,Raw_Data!$C:$C,$K11,Raw_Data!$K:$K,2026,Raw_Data!$M:$M,"LCL",Raw_Data!$L:$L,"IMPO",Raw_Data!$D:$D,Q$1) -> 0 | R11: =SUMIFS(Raw_Data!$G:$G,Raw_Data!$C:$C,$K11,Raw_Data!$K:$K,2026,Raw_Data!$M:$M,"LCL",Raw_Data!$L:$L,"IMPO",Raw_Data!$D:$D,R$1) -> 0 | S11: =SUMIFS(Raw_Data!$G:$G,Raw_Data!$C:$C,$K11,Raw_Data!$K:$K,2026,Raw_Data!$M:$M,"LCL",Raw_Data!$L:$L,"IMPO",Raw_Data!$D:$D,S$1) -> 0 | U11: 24 | V11: =SUMIFS(Raw_Data!$J:$J,Raw_Data!$C:$C,$K11,Raw_Data!$K:$K,2026,Raw_Data!$M:$M,"LCL",Raw_Data!$L:$L,"IMPO",Raw_Data!$D:$D,V$1) -> 0 | W11: =SUMIFS(Raw_Data!$J:$J,Raw_Data!$C:$C,$K11,Raw_Data!$K:$K,2026,Raw_Data!$M:$M,"LCL",Raw_Data!$L:$L,"IMPO",Raw_Data!$D:$D,W$1) -> 0 | X11: =SUMIFS(Raw_Data!$J:$J,Raw_Data!$C:$C,$K11,Raw_Data!$K:$K,2026,Raw_Data!$M:$M,"LCL",Raw_Data!$L:$L,"IMPO",Raw_Data!$D:$D,X$1) -> 0 | Y11: =SUMIFS(Raw_Data!$J:$J,Raw_Data!$C:$C,$K11,Raw_Data!$K:$K,2026,Raw_Data!$M:$M,"LCL",Raw_Data!$L:$L,"IMPO",Raw_Data!$D:$D,Y$1) -> 0 | Z11: =SUMIFS(Raw_Data!$J:$J,Raw_Data!$C:$C,$K11,Raw_Data!$K:$K,2026,Raw_Data!$M:$M,"LCL",Raw_Data!$L:$L,"IMPO",Raw_Data!$D:$D,Z$1) -> 0 | AA11: =SUMIFS(Raw_Data!$J:$J,Raw_Data!$C:$C,$K11,Raw_Data!$K:$K,2026,Raw_Data!$M:$M,"LCL",Raw_Data!$L:$L,"IMPO",Raw_Data!$D:$D,AA$1) -> 0 | AB11: =SUMIFS(Raw_Data!$J:$J,Raw_Data!$C:$C,$K11,Raw_Data!$K:$K,2026,Raw_Data!$M:$M,"LCL",Raw_Data!$L:$L,"IMPO",Raw_Data!$D:$D,AB$1) -> 0 | AC11: =SUMIFS(Raw_Data!$J:$J,Raw_Data!$C:$C,$K11,Raw_Data!$K:$K,2026,Raw_Data!$M:$M,"LCL",Raw_Data!$L:$L,"IMPO",Raw_Data!$D:$D,AC$1) -> 0
A12: 24 | B12: =SUMIFS(Raw_Data!$G:$G,Raw_Data!$C:$C,$A12,Raw_Data!$K:$K,B$2,Raw_Data!$M:$M,"LCL",Raw_Data!$L:$L,"IMPO") -> 0 | C12: =SUMIFS(Raw_Data!$G:$G,Raw_Data!$C:$C,$A12,Raw_Data!$K:$K,C$2,Raw_Data!$M:$M,"LCL",Raw_Data!$L:$L,"IMPO") -> 0 | F12: 24 | G12: =SUMIFS(Raw_Data!$G:$G,Raw_Data!$C:$C,$F12,Raw_Data!$K:$K,G$2,Raw_Data!$M:$M,"LCL",Raw_Data!$L:$L,"EXPO") -> 0 | H12: =SUMIFS(Raw_Data!$G:$G,Raw_Data!$C:$C,$F12,Raw_Data!$K:$K,H$2,Raw_Data!$M:$M,"LCL",Raw_Data!$L:$L,"EXPO") -> 0
A14: Week | B14: Coloader | C14: Consolidada | F14: Week | G14: Coloader | H14: Consolidada | K14: Week | L14: CPQ | M14: CWB | N14: ITJ | O14: MAO | P14: POA | Q14: RIO | R14: SAO | S14: SSA | U14: Week | V14: CPQ | W14: CWB | X14: ITJ | Y14: MAO | Z14: POA | AA14: RIO | AB14: SAO | AC14: SSA
A15: 15 | B15: =SUMIFS(Raw_Data!$G:$G,Raw_Data!$C:$C,$A15,Raw_Data!$K:$K,2026,Raw_Data!$M:$M,"LCL",Raw_Data!$L:$L,"IMPO",Raw_Data!$F:$F,"COLOADER") -> 98 | C15: =SUMIFS(Raw_Data!$G:$G,Raw_Data!$C:$C,$A15,Raw_Data!$K:$K,2026,Raw_Data!$M:$M,"LCL",Raw_Data!$L:$L,"IMPO",Raw_Data!$F:$F,"CONSOLIDADA") -> 138 | F15: 15 | G15: =SUMIFS(Raw_Data!$G:$G,Raw_Data!$C:$C,$F15,Raw_Data!$K:$K,2026,Raw_Data!$M:$M,"LCL",Raw_Data!$L:$L,"EXPO",Raw_Data!$F:$F,"COLOADER") -> 37 | H15: =SUMIFS(Raw_Data!$G:$G,Raw_Data!$C:$C,$F15,Raw_Data!$K:$K,2026,Raw_Data!$M:$M,"LCL",Raw_Data!$L:$L,"EXPO",Raw_Data!$F:$F,"CONSOLIDADA") -> 40 | K15: 15 | L15: =SUMIFS(Raw_Data!$J:$J,Raw_Data!$C:$C,$K15,Raw_Data!$K:$K,2026,Raw_Data!$M:$M,"LCL",Raw_Data!$L:$L,"EXPO",Raw_Data!$D:$D,L$14) -> 54.668 | M15: =SUMIFS(Raw_Data!$J:$J,Raw_Data!$C:$C,$K15,Raw_Data!$K:$K,2026,Raw_Data!$M:$M,"LCL",Raw_Data!$L:$L,"EXPO",Raw_Data!$D:$D,M$14) -> 5.28 | N15: =SUMIFS(Raw_Data!$J:$J,Raw_Data!$C:$C,$K15,Raw_Data!$K:$K,2026,Raw_Data!$M:$M,"LCL",Raw_Data!$L:$L,"EXPO",Raw_Data!$D:$D,N$14) -> 10.634 | O15: =SUMIFS(Raw_Data!$J:$J,Raw_Data!$C:$C,$K15,Raw_Data!$K:$K,2026,Raw_Data!$M:$M,"LCL",Raw_Data!$L:$L,"EXPO",Raw_Data!$D:$D,O$14) -> 0 | P15: =SUMIFS(Raw_Data!$J:$J,Raw_Data!$C:$C,$K15,Raw_Data!$K:$K,2026,Raw_Data!$M:$M,"LCL",Raw_Data!$L:$L,"EXPO",Raw_Data!$D:$D,P$14) -> 35.945 | Q15: =SUMIFS(Raw_Data!$J:$J,Raw_Data!$C:$C,$K15,Raw_Data!$K:$K,2026,Raw_Data!$M:$M,"LCL",Raw_Data!$L:$L,"EXPO",Raw_Data!$D:$D,Q$14) -> 3.466 | R15: =SUMIFS(Raw_Data!$J:$J,Raw_Data!$C:$C,$K15,Raw_Data!$K:$K,2026,Raw_Data!$M:$M,"LCL",Raw_Data!$L:$L,"EXPO",Raw_Data!$D:$D,R$14) -> 95.243 | S15: =SUMIFS(Raw_Data!$J:$J,Raw_Data!$C:$C,$K15,Raw_Data!$K:$K,2026,Raw_Data!$M:$M,"LCL",Raw_Data!$L:$L,"EXPO",Raw_Data!$D:$D,S$14) -> 0 | U15: 15 | V15: =SUMIFS(Raw_Data!$G:$G,Raw_Data!$C:$C,$U15,Raw_Data!$K:$K,2026,Raw_Data!$M:$M,"LCL",Raw_Data!$L:$L,"EXPO",Raw_Data!$D:$D,V$14) -> 38 | W15: =SUMIFS(Raw_Data!$G:$G,Raw_Data!$C:$C,$U15,Raw_Data!$K:$K,2026,Raw_Data!$M:$M,"LCL",Raw_Data!$L:$L,"EXPO",Raw_Data!$D:$D,W$14) -> 2 | X15: =SUMIFS(Raw_Data!$G:$G,Raw_Data!$C:$C,$U15,Raw_Data!$K:$K,2026,Raw_Data!$M:$M,"LCL",Raw_Data!$L:$L,"EXPO",Raw_Data!$D:$D,X$14) -> 2 | Y15: =SUMIFS(Raw_Data!$G:$G,Raw_Data!$C:$C,$U15,Raw_Data!$K:$K,2026,Raw_Data!$M:$M,"LCL",Raw_Data!$L:$L,"EXPO",Raw_Data!$D:$D,Y$14) -> 0 | Z15: =SUMIFS(Raw_Data!$G:$G,Raw_Data!$C:$C,$U15,Raw_Data!$K:$K,2026,Raw_Data!$M:$M,"LCL",Raw_Data!$L:$L,"EXPO",Raw_Data!$D:$D,Z$14) -> 11 | AA15: =SUMIFS(Raw_Data!$G:$G,Raw_Data!$C:$C,$U15,Raw_Data!$K:$K,2026,Raw_Data!$M:$M,"LCL",Raw_Data!$L:$L,"EXPO",Raw_Data!$D:$D,AA$14) -> 1 | AB15: =SUMIFS(Raw_Data!$G:$G,Raw_Data!$C:$C,$U15,Raw_Data!$K:$K,2026,Raw_Data!$M:$M,"LCL",Raw_Data!$L:$L,"EXPO",Raw_Data!$D:$D,AB$14) -> 23 | AC15: =SUMIFS(Raw_Data!$G:$G,Raw_Data!$C:$C,$U15,Raw_Data!$K:$K,2026,Raw_Data!$M:$M,"LCL",Raw_Data!$L:$L,"EXPO",Raw_Data!$D:$D,AC$14) -> 0
A16: 16 | B16: =SUMIFS(Raw_Data!$G:$G,Raw_Data!$C:$C,$A16,Raw_Data!$K:$K,2026,Raw_Data!$M:$M,"LCL",Raw_Data!$L:$L,"IMPO",Raw_Data!$F:$F,"COLOADER") -> 77 | C16: =SUMIFS(Raw_Data!$G:$G,Raw_Data!$C:$C,$A16,Raw_Data!$K:$K,2026,Raw_Data!$M:$M,"LCL",Raw_Data!$L:$L,"IMPO",Raw_Data!$F:$F,"CONSOLIDADA") -> 129 | F16: 16 | G16: =SUMIFS(Raw_Data!$G:$G,Raw_Data!$C:$C,$F16,Raw_Data!$K:$K,2026,Raw_Data!$M:$M,"LCL",Raw_Data!$L:$L,"EXPO",Raw_Data!$F:$F,"COLOADER") -> 61 | H16: =SUMIFS(Raw_Data!$G:$G,Raw_Data!$C:$C,$F16,Raw_Data!$K:$K,2026,Raw_Data!$M:$M,"LCL",Raw_Data!$L:$L,"EXPO",Raw_Data!$F:$F,"CONSOLIDADA") -> 58 | K16: 16 | L16: =SUMIFS(Raw_Data!$J:$J,Raw_Data!$C:$C,$K16,Raw_Data!$K:$K,2026,Raw_Data!$M:$M,"LCL",Raw_Data!$L:$L,"EXPO",Raw_Data!$D:$D,L$14) -> 129.706 | M16: =SUMIFS(Raw_Data!$J:$J,Raw_Data!$C:$C,$K16,Raw_Data!$K:$K,2026,Raw_Data!$M:$M,"LCL",Raw_Data!$L:$L,"EXPO",Raw_Data!$D:$D,M$14) -> 10.338 | N16: =SUMIFS(Raw_Data!$J:$J,Raw_Data!$C:$C,$K16,Raw_Data!$K:$K,2026,Raw_Data!$M:$M,"LCL",Raw_Data!$L:$L,"EXPO",Raw_Data!$D:$D,N$14) -> 1.094 | O16: =SUMIFS(Raw_Data!$J:$J,Raw_Data!$C:$C,$K16,Raw_Data!$K:$K,2026,Raw_Data!$M:$M,"LCL",Raw_Data!$L:$L,"EXPO",Raw_Data!$D:$D,O$14) -> 0 | P16: =SUMIFS(Raw_Data!$J:$J,Raw_Data!$C:$C,$K16,Raw_Data!$K:$K,2026,Raw_Data!$M:$M,"LCL",Raw_Data!$L:$L,"EXPO",Raw_Data!$D:$D,P$14) -> 75.245 | Q16: =SUMIFS(Raw_Data!$J:$J,Raw_Data!$C:$C,$K16,Raw_Data!$K:$K,2026,Raw_Data!$M:$M,"LCL",Raw_Data!$L:$L,"EXPO",Raw_Data!$D:$D,Q$14) -> 3.558 | R16: =SUMIFS(Raw_Data!$J:$J,Raw_Data!$C:$C,$K16,Raw_Data!$K:$K,2026,Raw_Data!$M:$M,"LCL",Raw_Data!$L:$L,"EXPO",Raw_Data!$D:$D,R$14) -> 96.719 | S16: =SUMIFS(Raw_Data!$J:$J,Raw_Data!$C:$C,$K16,Raw_Data!$K:$K,2026,Raw_Data!$M:$M,"LCL",Raw_Data!$L:$L,"EXPO",Raw_Data!$D:$D,S$14) -> 0 | U16: 16 | V16: =SUMIFS(Raw_Data!$G:$G,Raw_Data!$C:$C,$U16,Raw_Data!$K:$K,2026,Raw_Data!$M:$M,"LCL",Raw_Data!$L:$L,"EXPO",Raw_Data!$D:$D,V$14) -> 54 | W16: =SUMIFS(Raw_Data!$G:$G,Raw_Data!$C:$C,$U16,Raw_Data!$K:$K,2026,Raw_Data!$M:$M,"LCL",Raw_Data!$L:$L,"EXPO",Raw_Data!$D:$D,W$14) -> 6 | X16: =SUMIFS(Raw_Data!$G:$G,Raw_Data!$C:$C,$U16,Raw_Data!$K:$K,2026,Raw_Data!$M:$M,"LCL",Raw_Data!$L:$L,"EXPO",Raw_Data!$D:$D,X$14) -> 1 | Y16: =SUMIFS(Raw_Data!$G:$G,Raw_Data!$C:$C,$U16,Raw_Data!$K:$K,2026,Raw_Data!$M:$M,"LCL",Raw_Data!$L:$L,"EXPO",Raw_Data!$D:$D,Y$14) -> 0 | Z16: =SUMIFS(Raw_Data!$G:$G,Raw_Data!$C:$C,$U16,Raw_Data!$K:$K,2026,Raw_Data!$M:$M,"LCL",Raw_Data!$L:$L,"EXPO",Raw_Data!$D:$D,Z$14) -> 21 | AA16: =SUMIFS(Raw_Data!$G:$G,Raw_Data!$C:$C,$U16,Raw_Data!$K:$K,2026,Raw_Data!$M:$M,"LCL",Raw_Data!$L:$L,"EXPO",Raw_Data!$D:$D,AA$14) -> 4 | AB16: =SUMIFS(Raw_Data!$G:$G,Raw_Data!$C:$C,$U16,Raw_Data!$K:$K,2026,Raw_Data!$M:$M,"LCL",Raw_Data!$L:$L,"EXPO",Raw_Data!$D:$D,AB$14) -> 33 | AC16: =SUMIFS(Raw_Data!$G:$G,Raw_Data!$C:$C,$U16,Raw_Data!$K:$K,2026,Raw_Data!$M:$M,"LCL",Raw_Data!$L:$L,"EXPO",Raw_Data!$D:$D,AC$14) -> 0
A17: 17 | B17: =SUMIFS(Raw_Data!$G:$G,Raw_Data!$C:$C,$A17,Raw_Data!$K:$K,2026,Raw_Data!$M:$M,"LCL",Raw_Data!$L:$L,"IMPO",Raw_Data!$F:$F,"COLOADER") -> 102 | C17: =SUMIFS(Raw_Data!$G:$G,Raw_Data!$C:$C,$A17,Raw_Data!$K:$K,2026,Raw_Data!$M:$M,"LCL",Raw_Data!$L:$L,"IMPO",Raw_Data!$F:$F,"CONSOLIDADA") -> 83 | F17: 17 | G17: =SUMIFS(Raw_Data!$G:$G,Raw_Data!$C:$C,$F17,Raw_Data!$K:$K,2026,Raw_Data!$M:$M,"LCL",Raw_Data!$L:$L,"EXPO",Raw_Data!$F:$F,"COLOADER") -> 48 | H17: =SUMIFS(Raw_Data!$G:$G,Raw_Data!$C:$C,$F17,Raw_Data!$K:$K,2026,Raw_Data!$M:$M,"LCL",Raw_Data!$L:$L,"EXPO",Raw_Data!$F:$F,"CONSOLIDADA") -> 60 | K17: 17 | L17: =SUMIFS(Raw_Data!$J:$J,Raw_Data!$C:$C,$K17,Raw_Data!$K:$K,2026,Raw_Data!$M:$M,"LCL",Raw_Data!$L:$L,"EXPO",Raw_Data!$D:$D,L$14) -> 197.728 | M17: =SUMIFS(Raw_Data!$J:$J,Raw_Data!$C:$C,$K17,Raw_Data!$K:$K,2026,Raw_Data!$M:$M,"LCL",Raw_Data!$L:$L,"EXPO",Raw_Data!$D:$D,M$14) -> 15.18 | N17: =SUMIFS(Raw_Data!$J:$J,Raw_Data!$C:$C,$K17,Raw_Data!$K:$K,2026,Raw_Data!$M:$M,"LCL",Raw_Data!$L:$L,"EXPO",Raw_Data!$D:$D,N$14) -> 0 | O17: =SUMIFS(Raw_Data!$J:$J,Raw_Data!$C:$C,$K17,Raw_Data!$K:$K,2026,Raw_Data!$M:$M,"LCL",Raw_Data!$L:$L,"EXPO",Raw_Data!$D:$D,O$14) -> 0 | P17: =SUMIFS(Raw_Data!$J:$J,Raw_Data!$C:$C,$K17,Raw_Data!$K:$K,2026,Raw_Data!$M:$M,"LCL",Raw_Data!$L:$L,"EXPO",Raw_Data!$D:$D,P$14) -> 70.185 | Q17: =SUMIFS(Raw_Data!$J:$J,Raw_Data!$C:$C,$K17,Raw_Data!$K:$K,2026,Raw_Data!$M:$M,"LCL",Raw_Data!$L:$L,"EXPO",Raw_Data!$D:$D,Q$14) -> 0 | R17: =SUMIFS(Raw_Data!$J:$J,Raw_Data!$C:$C,$K17,Raw_Data!$K:$K,2026,Raw_Data!$M:$M,"LCL",Raw_Data!$L:$L,"EXPO",Raw_Data!$D:$D,R$14) -> 117.519 | S17: =SUMIFS(Raw_Data!$J:$J,Raw_Data!$C:$C,$K17,Raw_Data!$K:$K,2026,Raw_Data!$M:$M,"LCL",Raw_Data!$L:$L,"EXPO",Raw_Data!$D:$D,S$14) -> 0 | U17: 17 | V17: =SUMIFS(Raw_Data!$G:$G,Raw_Data!$C:$C,$U17,Raw_Data!$K:$K,2026,Raw_Data!$M:$M,"LCL",Raw_Data!$L:$L,"EXPO",Raw_Data!$D:$D,V$14) -> 70 | W17: =SUMIFS(Raw_Data!$G:$G,Raw_Data!$C:$C,$U17,Raw_Data!$K:$K,2026,Raw_Data!$M:$M,"LCL",Raw_Data!$L:$L,"EXPO",Raw_Data!$D:$D,W$14) -> 4 | X17: =SUMIFS(Raw_Data!$G:$G,Raw_Data!$C:$C,$U17,Raw_Data!$K:$K,2026,Raw_Data!$M:$M,"LCL",Raw_Data!$L:$L,"EXPO",Raw_Data!$D:$D,X$14) -> 0 | Y17: =SUMIFS(Raw_Data!$G:$G,Raw_Data!$C:$C,$U17,Raw_Data!$K:$K,2026,Raw_Data!$M:$M,"LCL",Raw_Data!$L:$L,"EXPO",Raw_Data!$D:$D,Y$14) -> 0 | Z17: =SUMIFS(Raw_Data!$G:$G,Raw_Data!$C:$C,$U17,Raw_Data!$K:$K,2026,Raw_Data!$M:$M,"LCL",Raw_Data!$L:$L,"EXPO",Raw_Data!$D:$D,Z$14) -> 13 | AA17: =SUMIFS(Raw_Data!$G:$G,Raw_Data!$C:$C,$U17,Raw_Data!$K:$K,2026,Raw_Data!$M:$M,"LCL",Raw_Data!$L:$L,"EXPO",Raw_Data!$D:$D,AA$14) -> 0 | AB17: =SUMIFS(Raw_Data!$G:$G,Raw_Data!$C:$C,$U17,Raw_Data!$K:$K,2026,Raw_Data!$M:$M,"LCL",Raw_Data!$L:$L,"EXPO",Raw_Data!$D:$D,AB$14) -> 20 | AC17: =SUMIFS(Raw_Data!$G:$G,Raw_Data!$C:$C,$U17,Raw_Data!$K:$K,2026,Raw_Data!$M:$M,"LCL",Raw_Data!$L:$L,"EXPO",Raw_Data!$D:$D,AC$14) -> 0
A18: 18 | B18: =SUMIFS(Raw_Data!$G:$G,Raw_Data!$C:$C,$A18,Raw_Data!$K:$K,2026,Raw_Data!$M:$M,"LCL",Raw_Data!$L:$L,"IMPO",Raw_Data!$F:$F,"COLOADER") -> 113 | C18: =SUMIFS(Raw_Data!$G:$G,Raw_Data!$C:$C,$A18,Raw_Data!$K:$K,2026,Raw_Data!$M:$M,"LCL",Raw_Data!$L:$L,"IMPO",Raw_Data!$F:$F,"CONSOLIDADA") -> 214 | F18: 18 | G18: =SUMIFS(Raw_Data!$G:$G,Raw_Data!$C:$C,$F18,Raw_Data!$K:$K,2026,Raw_Data!$M:$M,"LCL",Raw_Data!$L:$L,"EXPO",Raw_Data!$F:$F,"COLOADER") -> 40 | H18: =SUMIFS(Raw_Data!$G:$G,Raw_Data!$C:$C,$F18,Raw_Data!$K:$K,2026,Raw_Data!$M:$M,"LCL",Raw_Data!$L:$L,"EXPO",Raw_Data!$F:$F,"CONSOLIDADA") -> 52 | K18: 18 | L18: =SUMIFS(Raw_Data!$J:$J,Raw_Data!$C:$C,$K18,Raw_Data!$K:$K,2026,Raw_Data!$M:$M,"LCL",Raw_Data!$L:$L,"EXPO",Raw_Data!$D:$D,L$14) -> 134.274 | M18: =SUMIFS(Raw_Data!$J:$J,Raw_Data!$C:$C,$K18,Raw_Data!$K:$K,2026,Raw_Data!$M:$M,"LCL",Raw_Data!$L:$L,"EXPO",Raw_Data!$D:$D,M$14) -> 8.136 | N18: =SUMIFS(Raw_Data!$J:$J,Raw_Data!$C:$C,$K18,Raw_Data!$K:$K,2026,Raw_Data!$M:$M,"LCL",Raw_Data!$L:$L,"EXPO",Raw_Data!$D:$D,N$14) -> 11.865 | O18: =SUMIFS(Raw_Data!$J:$J,Raw_Data!$C:$C,$K18,Raw_Data!$K:$K,2026,Raw_Data!$M:$M,"LCL",Raw_Data!$L:$L,"EXPO",Raw_Data!$D:$D,O$14) -> 0.701 | P18: =SUMIFS(Raw_Data!$J:$J,Raw_Data!$C:$C,$K18,Raw_Data!$K:$K,2026,Raw_Data!$M:$M,"LCL",Raw_Data!$L:$L,"EXPO",Raw_Data!$D:$D,P$14) -> 24.635 | Q18: =SUMIFS(Raw_Data!$J:$J,Raw_Data!$C:$C,$K18,Raw_Data!$K:$K,2026,Raw_Data!$M:$M,"LCL",Raw_Data!$L:$L,"EXPO",Raw_Data!$D:$D,Q$14) -> 13.064 | R18: =SUMIFS(Raw_Data!$J:$J,Raw_Data!$C:$C,$K18,Raw_Data!$K:$K,2026,Raw_Data!$M:$M,"LCL",Raw_Data!$L:$L,"EXPO",Raw_Data!$D:$D,R$14) -> 65.401 | S18: =SUMIFS(Raw_Data!$J:$J,Raw_Data!$C:$C,$K18,Raw_Data!$K:$K,2026,Raw_Data!$M:$M,"LCL",Raw_Data!$L:$L,"EXPO",Raw_Data!$D:$D,S$14) -> 0 | U18: 18 | V18: =SUMIFS(Raw_Data!$G:$G,Raw_Data!$C:$C,$U18,Raw_Data!$K:$K,2026,Raw_Data!$M:$M,"LCL",Raw_Data!$L:$L,"EXPO",Raw_Data!$D:$D,V$14) -> 62 | W18: =SUMIFS(Raw_Data!$G:$G,Raw_Data!$C:$C,$U18,Raw_Data!$K:$K,2026,Raw_Data!$M:$M,"LCL",Raw_Data!$L:$L,"EXPO",Raw_Data!$D:$D,W$14) -> 4 | X18: =SUMIFS(Raw_Data!$G:$G,Raw_Data!$C:$C,$U18,Raw_Data!$K:$K,2026,Raw_Data!$M:$M,"LCL",Raw_Data!$L:$L,"EXPO",Raw_Data!$D:$D,X$14) -> 4 | Y18: =SUMIFS(Raw_Data!$G:$G,Raw_Data!$C:$C,$U18,Raw_Data!$K:$K,2026,Raw_Data!$M:$M,"LCL",Raw_Data!$L:$L,"EXPO",Raw_Data!$D:$D,Y$14) -> 1 | Z18: =SUMIFS(Raw_Data!$G:$G,Raw_Data!$C:$C,$U18,Raw_Data!$K:$K,2026,Raw_Data!$M:$M,"LCL",Raw_Data!$L:$L,"EXPO",Raw_Data!$D:$D,Z$14) -> 6 | AA18: =SUMIFS(Raw_Data!$G:$G,Raw_Data!$C:$C,$U18,Raw_Data!$K:$K,2026,Raw_Data!$M:$M,"LCL",Raw_Data!$L:$L,"EXPO",Raw_Data!$D:$D,AA$14) -> 3 | AB18: =SUMIFS(Raw_Data!$G:$G,Raw_Data!$C:$C,$U18,Raw_Data!$K:$K,2026,Raw_Data!$M:$M,"LCL",Raw_Data!$L:$L,"EXPO",Raw_Data!$D:$D,AB$14) -> 12 | AC18: =SUMIFS(Raw_Data!$G:$G,Raw_Data!$C:$C,$U18,Raw_Data!$K:$K,2026,Raw_Data!$M:$M,"LCL",Raw_Data!$L:$L,"EXPO",Raw_Data!$D:$D,AC$14) -> 0
A19: 19 | B19: =SUMIFS(Raw_Data!$G:$G,Raw_Data!$C:$C,$A19,Raw_Data!$K:$K,2026,Raw_Data!$M:$M,"LCL",Raw_Data!$L:$L,"IMPO",Raw_Data!$F:$F,"COLOADER") -> 95 | C19: =SUMIFS(Raw_Data!$G:$G,Raw_Data!$C:$C,$A19,Raw_Data!$K:$K,2026,Raw_Data!$M:$M,"LCL",Raw_Data!$L:$L,"IMPO",Raw_Data!$F:$F,"CONSOLIDADA") -> 122 | F19: 19 | G19: =SUMIFS(Raw_Data!$G:$G,Raw_Data!$C:$C,$F19,Raw_Data!$K:$K,2026,Raw_Data!$M:$M,"LCL",Raw_Data!$L:$L,"EXPO",Raw_Data!$F:$F,"COLOADER") -> 36 | H19: =SUMIFS(Raw_Data!$G:$G,Raw_Data!$C:$C,$F19,Raw_Data!$K:$K,2026,Raw_Data!$M:$M,"LCL",Raw_Data!$L:$L,"EXPO",Raw_Data!$F:$F,"CONSOLIDADA") -> 48 | K19: 19 | L19: =SUMIFS(Raw_Data!$J:$J,Raw_Data!$C:$C,$K19,Raw_Data!$K:$K,2026,Raw_Data!$M:$M,"LCL",Raw_Data!$L:$L,"EXPO",Raw_Data!$D:$D,L$14) -> 92.926 | M19: =SUMIFS(Raw_Data!$J:$J,Raw_Data!$C:$C,$K19,Raw_Data!$K:$K,2026,Raw_Data!$M:$M,"LCL",Raw_Data!$L:$L,"EXPO",Raw_Data!$D:$D,M$14) -> 1.22 | N19: =SUMIFS(Raw_Data!$J:$J,Raw_Data!$C:$C,$K19,Raw_Data!$K:$K,2026,Raw_Data!$M:$M,"LCL",Raw_Data!$L:$L,"EXPO",Raw_Data!$D:$D,N$14) -> 4.295 | O19: =SUMIFS(Raw_Data!$J:$J,Raw_Data!$C:$C,$K19,Raw_Data!$K:$K,2026,Raw_Data!$M:$M,"LCL",Raw_Data!$L:$L,"EXPO",Raw_Data!$D:$D,O$14) -> 0 | P19: =SUMIFS(Raw_Data!$J:$J,Raw_Data!$C:$C,$K19,Raw_Data!$K:$K,2026,Raw_Data!$M:$M,"LCL",Raw_Data!$L:$L,"EXPO",Raw_Data!$D:$D,P$14) -> 58.826 | Q19: =SUMIFS(Raw_Data!$J:$J,Raw_Data!$C:$C,$K19,Raw_Data!$K:$K,2026,Raw_Data!$M:$M,"LCL",Raw_Data!$L:$L,"EXPO",Raw_Data!$D:$D,Q$14) -> 9.255 | R19: =SUMIFS(Raw_Data!$J:$J,Raw_Data!$C:$C,$K19,Raw_Data!$K:$K,2026,Raw_Data!$M:$M,"LCL",Raw_Data!$L:$L,"EXPO",Raw_Data!$D:$D,R$14) -> 41.257 | S19: =SUMIFS(Raw_Data!$J:$J,Raw_Data!$C:$C,$K19,Raw_Data!$K:$K,2026,Raw_Data!$M:$M,"LCL",Raw_Data!$L:$L,"EXPO",Raw_Data!$D:$D,S$14) -> 0 | U19: 19 | V19: =SUMIFS(Raw_Data!$G:$G,Raw_Data!$C:$C,$U19,Raw_Data!$K:$K,2026,Raw_Data!$M:$M,"LCL",Raw_Data!$L:$L,"EXPO",Raw_Data!$D:$D,V$14) -> 50 | W19: =SUMIFS(Raw_Data!$G:$G,Raw_Data!$C:$C,$U19,Raw_Data!$K:$K,2026,Raw_Data!$M:$M,"LCL",Raw_Data!$L:$L,"EXPO",Raw_Data!$D:$D,W$14) -> 1 | X19: =SUMIFS(Raw_Data!$G:$G,Raw_Data!$C:$C,$U19,Raw_Data!$K:$K,2026,Raw_Data!$M:$M,"LCL",Raw_Data!$L:$L,"EXPO",Raw_Data!$D:$D,X$14) -> 2 | Y19: =SUMIFS(Raw_Data!$G:$G,Raw_Data!$C:$C,$U19,Raw_Data!$K:$K,2026,Raw_Data!$M:$M,"LCL",Raw_Data!$L:$L,"EXPO",Raw_Data!$D:$D,Y$14) -> 0 | Z19: =SUMIFS(Raw_Data!$G:$G,Raw_Data!$C:$C,$U19,Raw_Data!$K:$K,2026,Raw_Data!$M:$M,"LCL",Raw_Data!$L:$L,"EXPO",Raw_Data!$D:$D,Z$14) -> 14 | AA19: =SUMIFS(Raw_Data!$G:$G,Raw_Data!$C:$C,$U19,Raw_Data!$K:$K,2026,Raw_Data!$M:$M,"LCL",Raw_Data!$L:$L,"EXPO",Raw_Data!$D:$D,AA$14) -> 3 | AB19: =SUMIFS(Raw_Data!$G:$G,Raw_Data!$C:$C,$U19,Raw_Data!$K:$K,2026,Raw_Data!$M:$M,"LCL",Raw_Data!$L:$L,"EXPO",Raw_Data!$D:$D,AB$14) -> 14 | AC19: =SUMIFS(Raw_Data!$G:$G,Raw_Data!$C:$C,$U19,Raw_Data!$K:$K,2026,Raw_Data!$M:$M,"LCL",Raw_Data!$L:$L,"EXPO",Raw_Data!$D:$D,AC$14) -> 0
A20: 20 | B20: =SUMIFS(Raw_Data!$G:$G,Raw_Data!$C:$C,$A20,Raw_Data!$K:$K,2026,Raw_Data!$M:$M,"LCL",Raw_Data!$L:$L,"IMPO",Raw_Data!$F:$F,"COLOADER") -> 61 | C20: =SUMIFS(Raw_Data!$G:$G,Raw_Data!$C:$C,$A20,Raw_Data!$K:$K,2026,Raw_Data!$M:$M,"LCL",Raw_Data!$L:$L,"IMPO",Raw_Data!$F:$F,"CONSOLIDADA") -> 88 | F20: 20 | G20: =SUMIFS(Raw_Data!$G:$G,Raw_Data!$C:$C,$F20,Raw_Data!$K:$K,2026,Raw_Data!$M:$M,"LCL",Raw_Data!$L:$L,"EXPO",Raw_Data!$F:$F,"COLOADER") -> 45 | H20: =SUMIFS(Raw_Data!$G:$G,Raw_Data!$C:$C,$F20,Raw_Data!$K:$K,2026,Raw_Data!$M:$M,"LCL",Raw_Data!$L:$L,"EXPO",Raw_Data!$F:$F,"CONSOLIDADA") -> 68 | K20: 20 | L20: =SUMIFS(Raw_Data!$J:$J,Raw_Data!$C:$C,$K20,Raw_Data!$K:$K,2026,Raw_Data!$M:$M,"LCL",Raw_Data!$L:$L,"EXPO",Raw_Data!$D:$D,L$14) -> 258.083 | M20: =SUMIFS(Raw_Data!$J:$J,Raw_Data!$C:$C,$K20,Raw_Data!$K:$K,2026,Raw_Data!$M:$M,"LCL",Raw_Data!$L:$L,"EXPO",Raw_Data!$D:$D,M$14) -> 0 | N20: =SUMIFS(Raw_Data!$J:$J,Raw_Data!$C:$C,$K20,Raw_Data!$K:$K,2026,Raw_Data!$M:$M,"LCL",Raw_Data!$L:$L,"EXPO",Raw_Data!$D:$D,N$14) -> 6.082 | O20: =SUMIFS(Raw_Data!$J:$J,Raw_Data!$C:$C,$K20,Raw_Data!$K:$K,2026,Raw_Data!$M:$M,"LCL",Raw_Data!$L:$L,"EXPO",Raw_Data!$D:$D,O$14) -> 0 | P20: =SUMIFS(Raw_Data!$J:$J,Raw_Data!$C:$C,$K20,Raw_Data!$K:$K,2026,Raw_Data!$M:$M,"LCL",Raw_Data!$L:$L,"EXPO",Raw_Data!$D:$D,P$14) -> 36.065 | Q20: =SUMIFS(Raw_Data!$J:$J,Raw_Data!$C:$C,$K20,Raw_Data!$K:$K,2026,Raw_Data!$M:$M,"LCL",Raw_Data!$L:$L,"EXPO",Raw_Data!$D:$D,Q$14) -> 5.396 | R20: =SUMIFS(Raw_Data!$J:$J,Raw_Data!$C:$C,$K20,Raw_Data!$K:$K,2026,Raw_Data!$M:$M,"LCL",Raw_Data!$L:$L,"EXPO",Raw_Data!$D:$D,R$14) -> 75.791 | S20: =SUMIFS(Raw_Data!$J:$J,Raw_Data!$C:$C,$K20,Raw_Data!$K:$K,2026,Raw_Data!$M:$M,"LCL",Raw_Data!$L:$L,"EXPO",Raw_Data!$D:$D,S$14) -> 0 | U20: 20 | V20: =SUMIFS(Raw_Data!$G:$G,Raw_Data!$C:$C,$U20,Raw_Data!$K:$K,2026,Raw_Data!$M:$M,"LCL",Raw_Data!$L:$L,"EXPO",Raw_Data!$D:$D,V$14) -> 78 | W20: =SUMIFS(Raw_Data!$G:$G,Raw_Data!$C:$C,$U20,Raw_Data!$K:$K,2026,Raw_Data!$M:$M,"LCL",Raw_Data!$L:$L,"EXPO",Raw_Data!$D:$D,W$14) -> 0 | X20: =SUMIFS(Raw_Data!$G:$G,Raw_Data!$C:$C,$U20,Raw_Data!$K:$K,2026,Raw_Data!$M:$M,"LCL",Raw_Data!$L:$L,"EXPO",Raw_Data!$D:$D,X$14) -> 1 | Y20: =SUMIFS(Raw_Data!$G:$G,Raw_Data!$C:$C,$U20,Raw_Data!$K:$K,2026,Raw_Data!$M:$M,"LCL",Raw_Data!$L:$L,"EXPO",Raw_Data!$D:$D,Y$14) -> 0 | Z20: =SUMIFS(Raw_Data!$G:$G,Raw_Data!$C:$C,$U20,Raw_Data!$K:$K,2026,Raw_Data!$M:$M,"LCL",Raw_Data!$L:$L,"EXPO",Raw_Data!$D:$D,Z$14) -> 11 | AA20: =SUMIFS(Raw_Data!$G:$G,Raw_Data!$C:$C,$U20,Raw_Data!$K:$K,2026,Raw_Data!$M:$M,"LCL",Raw_Data!$L:$L,"EXPO",Raw_Data!$D:$D,AA$14) -> 4 | AB20: =SUMIFS(Raw_Data!$G:$G,Raw_Data!$C:$C,$U20,Raw_Data!$K:$K,2026,Raw_Data!$M:$M,"LCL",Raw_Data!$L:$L,"EXPO",Raw_Data!$D:$D,AB$14) -> 19 | AC20: =SUMIFS(Raw_Data!$G:$G,Raw_Data!$C:$C,$U20,Raw_Data!$K:$K,2026,Raw_Data!$M:$M,"LCL",Raw_Data!$L:$L,"EXPO",Raw_Data!$D:$D,AC$14) -> 0
A21: 21 | B21: =SUMIFS(Raw_Data!$G:$G,Raw_Data!$C:$C,$A21,Raw_Data!$K:$K,2026,Raw_Data!$M:$M,"LCL",Raw_Data!$L:$L,"IMPO",Raw_Data!$F:$F,"COLOADER") -> 0 | C21: =SUMIFS(Raw_Data!$G:$G,Raw_Data!$C:$C,$A21,Raw_Data!$K:$K,2026,Raw_Data!$M:$M,"LCL",Raw_Data!$L:$L,"IMPO",Raw_Data!$F:$F,"CONSOLIDADA") -> 0 | F21: 21 | G21: =SUMIFS(Raw_Data!$G:$G,Raw_Data!$C:$C,$F21,Raw_Data!$K:$K,2026,Raw_Data!$M:$M,"LCL",Raw_Data!$L:$L,"EXPO",Raw_Data!$F:$F,"COLOADER") -> 0 | H21: =SUMIFS(Raw_Data!$G:$G,Raw_Data!$C:$C,$F21,Raw_Data!$K:$K,2026,Raw_Data!$M:$M,"LCL",Raw_Data!$L:$L,"EXPO",Raw_Data!$F:$F,"CONSOLIDADA") -> 0 | K21: 21 | L21: =SUMIFS(Raw_Data!$J:$J,Raw_Data!$C:$C,$K21,Raw_Data!$K:$K,2026,Raw_Data!$M:$M,"LCL",Raw_Data!$L:$L,"EXPO",Raw_Data!$D:$D,L$14) -> 0 | M21: =SUMIFS(Raw_Data!$J:$J,Raw_Data!$C:$C,$K21,Raw_Data!$K:$K,2026,Raw_Data!$M:$M,"LCL",Raw_Data!$L:$L,"EXPO",Raw_Data!$D:$D,M$14) -> 0 | N21: =SUMIFS(Raw_Data!$J:$J,Raw_Data!$C:$C,$K21,Raw_Data!$K:$K,2026,Raw_Data!$M:$M,"LCL",Raw_Data!$L:$L,"EXPO",Raw_Data!$D:$D,N$14) -> 0 | O21: =SUMIFS(Raw_Data!$J:$J,Raw_Data!$C:$C,$K21,Raw_Data!$K:$K,2026,Raw_Data!$M:$M,"LCL",Raw_Data!$L:$L,"EXPO",Raw_Data!$D:$D,O$14) -> 0 | P21: =SUMIFS(Raw_Data!$J:$J,Raw_Data!$C:$C,$K21,Raw_Data!$K:$K,2026,Raw_Data!$M:$M,"LCL",Raw_Data!$L:$L,"EXPO",Raw_Data!$D:$D,P$14) -> 0 | Q21: =SUMIFS(Raw_Data!$J:$J,Raw_Data!$C:$C,$K21,Raw_Data!$K:$K,2026,Raw_Data!$M:$M,"LCL",Raw_Data!$L:$L,"EXPO",Raw_Data!$D:$D,Q$14) -> 0 | R21: =SUMIFS(Raw_Data!$J:$J,Raw_Data!$C:$C,$K21,Raw_Data!$K:$K,2026,Raw_Data!$M:$M,"LCL",Raw_Data!$L:$L,"EXPO",Raw_Data!$D:$D,R$14) -> 0 | S21: =SUMIFS(Raw_Data!$J:$J,Raw_Data!$C:$C,$K21,Raw_Data!$K:$K,2026,Raw_Data!$M:$M,"LCL",Raw_Data!$L:$L,"EXPO",Raw_Data!$D:$D,S$14) -> 0 | U21: 21 | V21: =SUMIFS(Raw_Data!$G:$G,Raw_Data!$C:$C,$U21,Raw_Data!$K:$K,2026,Raw_Data!$M:$M,"LCL",Raw_Data!$L:$L,"EXPO",Raw_Data!$D:$D,V$14) -> 0 | W21: =SUMIFS(Raw_Data!$G:$G,Raw_Data!$C:$C,$U21,Raw_Data!$K:$K,2026,Raw_Data!$M:$M,"LCL",Raw_Data!$L:$L,"EXPO",Raw_Data!$D:$D,W$14) -> 0 | X21: =SUMIFS(Raw_Data!$G:$G,Raw_Data!$C:$C,$U21,Raw_Data!$K:$K,2026,Raw_Data!$M:$M,"LCL",Raw_Data!$L:$L,"EXPO",Raw_Data!$D:$D,X$14) -> 0 | Y21: =SUMIFS(Raw_Data!$G:$G,Raw_Data!$C:$C,$U21,Raw_Data!$K:$K,2026,Raw_Data!$M:$M,"LCL",Raw_Data!$L:$L,"EXPO",Raw_Data!$D:$D,Y$14) -> 0 | Z21: =SUMIFS(Raw_Data!$G:$G,Raw_Data!$C:$C,$U21,Raw_Data!$K:$K,2026,Raw_Data!$M:$M,"LCL",Raw_Data!$L:$L,"EXPO",Raw_Data!$D:$D,Z$14) -> 0 | AA21: =SUMIFS(Raw_Data!$G:$G,Raw_Data!$C:$C,$U21,Raw_Data!$K:$K,2026,Raw_Data!$M:$M,"LCL",Raw_Data!$L:$L,"EXPO",Raw_Data!$D:$D,AA$14) -> 0 | AB21: =SUMIFS(Raw_Data!$G:$G,Raw_Data!$C:$C,$U21,Raw_Data!$K:$K,2026,Raw_Data!$M:$M,"LCL",Raw_Data!$L:$L,"EXPO",Raw_Data!$D:$D,AB$14) -> 0 | AC21: =SUMIFS(Raw_Data!$G:$G,Raw_Data!$C:$C,$U21,Raw_Data!$K:$K,2026,Raw_Data!$M:$M,"LCL",Raw_Data!$L:$L,"EXPO",Raw_Data!$D:$D,AC$14) -> 0
A22: 22 | B22: =SUMIFS(Raw_Data!$G:$G,Raw_Data!$C:$C,$A22,Raw_Data!$K:$K,2026,Raw_Data!$M:$M,"LCL",Raw_Data!$L:$L,"IMPO",Raw_Data!$F:$F,"COLOADER") -> 0 | C22: =SUMIFS(Raw_Data!$G:$G,Raw_Data!$C:$C,$A22,Raw_Data!$K:$K,2026,Raw_Data!$M:$M,"LCL",Raw_Data!$L:$L,"IMPO",Raw_Data!$F:$F,"CONSOLIDADA") -> 0 | F22: 22 | G22: =SUMIFS(Raw_Data!$G:$G,Raw_Data!$C:$C,$F22,Raw_Data!$K:$K,2026,Raw_Data!$M:$M,"LCL",Raw_Data!$L:$L,"EXPO",Raw_Data!$F:$F,"COLOADER") -> 0 | H22: =SUMIFS(Raw_Data!$G:$G,Raw_Data!$C:$C,$F22,Raw_Data!$K:$K,2026,Raw_Data!$M:$M,"LCL",Raw_Data!$L:$L,"EXPO",Raw_Data!$F:$F,"CONSOLIDADA") -> 0 | K22: 22 | L22: =SUMIFS(Raw_Data!$J:$J,Raw_Data!$C:$C,$K22,Raw_Data!$K:$K,2026,Raw_Data!$M:$M,"LCL",Raw_Data!$L:$L,"EXPO",Raw_Data!$D:$D,L$14) -> 0 | M22: =SUMIFS(Raw_Data!$J:$J,Raw_Data!$C:$C,$K22,Raw_Data!$K:$K,2026,Raw_Data!$M:$M,"LCL",Raw_Data!$L:$L,"EXPO",Raw_Data!$D:$D,M$14) -> 0 | N22: =SUMIFS(Raw_Data!$J:$J,Raw_Data!$C:$C,$K22,Raw_Data!$K:$K,2026,Raw_Data!$M:$M,"LCL",Raw_Data!$L:$L,"EXPO",Raw_Data!$D:$D,N$14) -> 0 | O22: =SUMIFS(Raw_Data!$J:$J,Raw_Data!$C:$C,$K22,Raw_Data!$K:$K,2026,Raw_Data!$M:$M,"LCL",Raw_Data!$L:$L,"EXPO",Raw_Data!$D:$D,O$14) -> 0 | P22: =SUMIFS(Raw_Data!$J:$J,Raw_Data!$C:$C,$K22,Raw_Data!$K:$K,2026,Raw_Data!$M:$M,"LCL",Raw_Data!$L:$L,"EXPO",Raw_Data!$D:$D,P$14) -> 0 | Q22: =SUMIFS(Raw_Data!$J:$J,Raw_Data!$C:$C,$K22,Raw_Data!$K:$K,2026,Raw_Data!$M:$M,"LCL",Raw_Data!$L:$L,"EXPO",Raw_Data!$D:$D,Q$14) -> 0 | R22: =SUMIFS(Raw_Data!$J:$J,Raw_Data!$C:$C,$K22,Raw_Data!$K:$K,2026,Raw_Data!$M:$M,"LCL",Raw_Data!$L:$L,"EXPO",Raw_Data!$D:$D,R$14) -> 0 | S22: =SUMIFS(Raw_Data!$J:$J,Raw_Data!$C:$C,$K22,Raw_Data!$K:$K,2026,Raw_Data!$M:$M,"LCL",Raw_Data!$L:$L,"EXPO",Raw_Data!$D:$D,S$14) -> 0 | U22: 22 | V22: =SUMIFS(Raw_Data!$G:$G,Raw_Data!$C:$C,$U22,Raw_Data!$K:$K,2026,Raw_Data!$M:$M,"LCL",Raw_Data!$L:$L,"EXPO",Raw_Data!$D:$D,V$14) -> 0 | W22: =SUMIFS(Raw_Data!$G:$G,Raw_Data!$C:$C,$U22,Raw_Data!$K:$K,2026,Raw_Data!$M:$M,"LCL",Raw_Data!$L:$L,"EXPO",Raw_Data!$D:$D,W$14) -> 0 | X22: =SUMIFS(Raw_Data!$G:$G,Raw_Data!$C:$C,$U22,Raw_Data!$K:$K,2026,Raw_Data!$M:$M,"LCL",Raw_Data!$L:$L,"EXPO",Raw_Data!$D:$D,X$14) -> 0 | Y22: =SUMIFS(Raw_Data!$G:$G,Raw_Data!$C:$C,$U22,Raw_Data!$K:$K,2026,Raw_Data!$M:$M,"LCL",Raw_Data!$L:$L,"EXPO",Raw_Data!$D:$D,Y$14) -> 0 | Z22: =SUMIFS(Raw_Data!$G:$G,Raw_Data!$C:$C,$U22,Raw_Data!$K:$K,2026,Raw_Data!$M:$M,"LCL",Raw_Data!$L:$L,"EXPO",Raw_Data!$D:$D,Z$14) -> 0 | AA22: =SUMIFS(Raw_Data!$G:$G,Raw_Data!$C:$C,$U22,Raw_Data!$K:$K,2026,Raw_Data!$M:$M,"LCL",Raw_Data!$L:$L,"EXPO",Raw_Data!$D:$D,AA$14) -> 0 | AB22: =SUMIFS(Raw_Data!$G:$G,Raw_Data!$C:$C,$U22,Raw_Data!$K:$K,2026,Raw_Data!$M:$M,"LCL",Raw_Data!$L:$L,"EXPO",Raw_Data!$D:$D,AB$14) -> 0 | AC22: =SUMIFS(Raw_Data!$G:$G,Raw_Data!$C:$C,$U22,Raw_Data!$K:$K,2026,Raw_Data!$M:$M,"LCL",Raw_Data!$L:$L,"EXPO",Raw_Data!$D:$D,AC$14) -> 0
